Workbook

Sheet Инструкция к работе
A1: Инструкция по работе:
A3: Нужно заполнить листы Москва, СПб, Новосибирск и Екатеринбург.
A5: Информацию нужно брать с листов Фрахт, Drop Off, ж.д. и Охрана
A7: Примечания:
A8: 1. Трансконтейнер в папке Фрахт содержит сразу конечную стоимость перевозки до конкретных назначений. Там не нужно дополнительно ничего складывать из других листов
A9: 2. Стоимость до разных городов зависит от стоимость дропа в городах и жд до этого города. Внимательно обращайте на это внимание при работе. Фрахт же не зависит от города назначения. Он одинаковый вне зависимости от города.

Sheet Фрахт
A2: POD | B2: Линия | C2: POL | D2: Фрахт
D4: 20 | E4: 40
A5: NINGBO | B5: HUAXIN | C5: СОЛЛЕРС | D5: 4336 | E5: 7272
A6: SHANGHAI | B6: HUAXIN (TAICANG) | C6: СОЛЛЕРС | D6: 4086 | E6: 6872
A7: QINGDAO | B7: HUAXIN | C7: СОЛЛЕРС | D7: 4086 | E7: 6872
A8: XIAMEN | B8: HUAXIN | C8: СОЛЛЕРС | D8: 4436 | E8: 7372
A9: XINGANG | B9: HUAXIN | C9: СОЛЛЕРС | D9: 4586 | E9: 7572
A10: YANTIAN | B10: HUAXIN | C10: СОЛЛЕРС | D10: 4586 | E10: 7572
A12: NINGBO | B12: ТоргМолл | C12: ВСК | D12: 3600 | E12: 6400
A13: SHANGHAI | B13: ТоргМолл | C13: ВСК | D13: 3600 | E13: 6000
A14: QINGDAO | B14: ТоргМолл | C14: ВСК | D14: 3600 | E14: 6000
A15: XIAMEN | B15: ТоргМолл (Taicang) | C15: ВСК | D15: - | E15: -
A16: XINGANG | B16: ТоргМолл | C16: ВСК | D16: 3600 | E16: 6000
A17: YANTIAN | B17: ТоргМолл | C17: ВСК | D17: - | E17: -
A19: NINGBO | B19: EuroEast | C19: СОЛЛЕРС | D19: 4350 | E19: 6215
A20: SHANGHAI | B20: EuroEast | C20: СОЛЛЕРС | D20: - | E20: -
A21: QINGDAO | B21: EuroEast | C21: СОЛЛЕРС | D21: 4350 | E21: 6215
A22: XIAMEN | B22: EuroEast | C22: СОЛЛЕРС | D22: - | E22: -
A23: XINGANG | B23: EuroEast | C23: СОЛЛЕРС | D23: - | E23: -
A24: YANTIAN | B24: EuroEast | C24: СОЛЛЕРС | D24: - | E24: -
A26: NINGBO | B26: ФЕСКО | C26: ВМТП (Феско) | D26: 5500 | E26: 7500
A27: SHANGHAI | B27: ФЕСКО | C27: ВМТП (Феско) | D27: 5500 | E27: 7500
A28: QINGDAO | B28: ФЕСКО | C28: ВМТП (Феско) | D28: 5500 | E28: 7500
A29: XIAMEN | B29: ФЕСКО | C29: ВМТП (Феско) | D29: 5500 | E29: 8500
A30: XINGANG | B30: ФЕСКО | C30: ВМТП (Феско) | D30: 5500 | E30: 7500
A31: YANTIAN | B31: ФЕСКО | C31: ВМТП (Феско) | D31: 5500 | E31: 8500
A33: NINGBO | B33: SINOKOR | C33: ВСК | D33: 4725 | E33: 7875
A34: SHANGHAI | B34: SINOKOR | C34: ВСК | D34: 4725 | E34: 7875
A35: QINGDAO | B35: SINOKOR | C35: ВСК | D35: 4725 | E35: 7875
A36: XIAMEN | B36: SINOKOR | C36: ВСК | D36: 5250 | E36: 7875
A37: XINGANG | B37: SINOKOR | C37: ВСК | D37: 4725 | E37: 7875
A38: YANTIAN | B38: SINOKOR | C38: ВСК | D38: 5775 | E38: 8400
... A63: QINGDAO | B63: SASCO | C63: ВМКТ | D63: 4700 | E63: 5700
A64: XIAMEN | B64: SASCO | C64: ВМКТ | D64: - | E64: -
A65: XINGANG | B65: SASCO | C65: ВМКТ | D65: - | E65: -
A66: YANTIAN | B66: SASCO | C66: ВМКТ | D66: - | E66: -
A68: NINGBO | B68: Хасан | C68: Соллерс (Хасан) | D68: 4430 | E68: 5720
A69: SHANGHAI | B69: Хасан | C69: Соллерс (Хасан) | D69: - | E69: -
A70: QINGDAO | B70: Хасан | C70: Соллерс (Хасан) | D70: 3914 | E70: 5720
A71: XIAMEN | B71: Хасан | C71: Соллерс (Хасан) | D71: - | E71: -
...

Sheet Фрахт Транс
A1: У ТрансКонтейнера ставки фрахт + ЖД. У них сразу итоговый вариант ставки без разбивки.
B2: Москва | E2: СПб | H2: Новосибирск | K2: Екатеринбург
B3: Москва | C3: Москва | D3: Москва | E3: СПб | F3: СПб | G3: СПб | H3: Новосибирск | I3: Новосибирск | J3: Новосибирск | K3: Екатеринбург | L3: Екатеринбург | M3: Екатеринбург
B4: 20<24т | C4: 20<28т | D4: 40 | E4: 20<24т | F4: 20<28т | G4: 40 | H4: 20<24т | I4: 20<28т | J4: 40 | K4: 20<24т | L4: 20<28т | M4: 40
A5: ВСК (ТК) Ningbo | B5: 354626 | C5: 372164 | D5: 566328 | E5: 345130 | F5: 363122 | G5: 573573 | H5: 330537 | I5: 344442 | J5: 524386 | K5: 336212 | L5: 351706 | M5: 535736
A6: ВСК (ТК) Shanghai | B6: 356456 | C6: 373994 | D6: 519968 | E6: 346960 | F6: 364952 | G6: 527213 | H6: 332367 | I6: 346272 | J6: 478026 | K6: 338042 | L6: 353536 | M6: 489376
A7: ВСК (ТК) Qingdao | B7: 356456 | C7: 373994 | D7: 532168 | E7: 346960 | F7: 364952 | G7: 539413 | H7: 332367 | I7: 346272 | J7: 490226 | K7: 338042 | L7: 353536 | M7: 501576
A8: ВСК (ТК) Xiamen | B8: 423556 | C8: 441094 | D8: 599268 | E8: 414060 | F8: 432052 | G8: 606513 | H8: 399467 | I8: 413372 | J8: 557326 | K8: 405142 | L8: 420636 | M8: 568676
A9: ВСК (ТК) Xingang | B9: 356456 | C9: 373994 | D9: 538268 | E9: 346960 | F9: 364952 | G9: 545513 | H9: 332367 | I9: 346272 | J9: 496326 | K9: 338042 | L9: 353536 | M9: 507676
A10: ВСК (ТК) Yantian | B10: 399156 | C10: 416694 | D10: 587068 | E10: 389660 | F10: 407652 | G10: 594313 | H10: 375067 | I10: 388972 | J10: 545126 | K10: 380742 | L10: 396236 | M10: 556476

Sheet Drop off
A2: Линия | B2: Локация
B3: Москва | D3: СПб | F3: Новосибирск | H3: Екатеринбург
B4: Москва | C4: Москва | D4: СПб | E4: СПб | F4: Новосибирск | G4: Новосибирск | H4: Екатеринбург | I4: Екатеринбург
B5: 20 | C5: 40 | D5: 20 | E5: 40 | F5: 20 | G5: 40 | H5: 20 | I5: 40
A6: Трансконтейнер (Сквозной сервис) | B6: 0 | C6: 0 | D6: 0 | E6: 0 | F6: 0 | G6: 0 | H6: 0 | I6: 0
A7: Хасан | B7: 100 | C7: 100 | D7: - | E7: - | F7: 450 | G7: 450 | H7: 450 | I7: 450
A8: SASCO | B8: 0 | C8: 0 | D8: 0 | E8: 0 | F8: 0 | G8: 0 | H8: 0 | I8: 0
A9: ТоргМолл (Taicang) | B9: 0 | C9: 0 | D9: 0 | E9: 0 | F9: 0 | G9: 0 | H9: 0 | I9: 0
A10: ФЕСКО | B10: 0 | C10: 0 | D10: 0 | E10: 0 | F10: 0 | G10: 0 | H10: 0 | I10: 0
A11: SINOKOR | B11: 945 | C11: 630 | D11: 1260 | E11: 945 | F11: 945 | G11: 630 | H11: 630 | I11: 945
A12: HUAXIN | B12: 700 | C12: 700 | D12: 0 | E12: 0 | F12: 150 | G12: 150 | H12: 300 | I12: 300
A13: ТоргМолл | B13: 0 | C13: 0 | D13: 0 | E13: 0 | F13: 0 | G13: 0 | H13: 0 | I13: 0
A14: EuroEast | B14: 0 | C14: 0 | D14: 0 | E14: 0 | F14: 0 | G14: 0 | H14: 0 | I14: 0

Sheet ж.д.
O1: 16 значений
A2: Терминал | B2: Локация
B3: Москва | E3: СПб | H3: Новосибирск | K3: Екатеринбург
B4: Москва | C4: Москва | D4: Москва | E4: СПб | F4: СПб | G4: СПб | H4: Новосибирск | I4: Новосибирск | J4: Новосибирск | K4: Екатеринбург | L4: Екатеринбург | M4: Екатеринбург
B5: 20<24т | C5: 20<28т | D5: 40 | E5: 20<24т | F5: 20<28т | G5: 40 | H5: 20<24т | I5: 20<28т | J5: 40 | K5: 20<24т | L5: 20<28т | M5: 40
A6: ВСК | B6: 122400 | C6: 139800 | D6: 224600 | E6: 124800 | F6: 143000 | G6: 211800 | H6: 99200 | I6: 113100 | J6: 176500 | K6: 105900 | L6: 122100 | M6: 196200
A7: ВМТП | B7: 141000 | C7: 156600 | D7: 261000 | E7: 125800 | F7: 141805 | G7: 211100 | H7: 103000 | I7: 115325 | J7: 184000 | K7: 109000 | L7: 122755 | M7: 203500
A8: ВМКТ | B8: 125000 | C8: 140000 | D8: 227000 | E8: 120000 | F8: 137000 | G8: 200000 | H8: 101000 | I8: 115000 | J8: 175000 | K8: 105000 | L8: 120000 | M8: 192000
A9: ВМПП | B9: 134400 | C9: 149400 | D9: 235000 | E9: 107400 | F9: 123400 | G9: 187400 | H9: 103900 | I9: 114900 | J9: 182400 | K9: 108400 | L9: 122400 | M9: 200400
A10: СОЛЛЕРС | B10: 134400 | C10: 149400 | D10: 235000 | E10: 107400 | F10: 123400 | G10: 187400 | H10: 103900 | I10: 114900 | J10: 182400 | K10: 108400 | L10: 122400 | M10: 200400
A11: ВМТП (Феско) | B11: 167600 | C11: 181540 | D11: 292000 | E11: 144300 | F11: 160305 | G11: 247100 | H11: 93100 | I11: 104115 | J11: 168000 | K11: 97300 | L11: 109595 | M11: 195500
A12: ВМТП (Феско ост.) | B12: 173730 | C12: 191045 | D12: 303815 | E12: 150590 | F12: 168355 | G12: 259240 | H12: 97945 | I12: 111625 | J12: 177245 | K12: 102705 | L12: 117975 | M12: 205870
A13: Соллерс (Хасан) | B13: 122400 | C13: 139800 | D13: 155000 | E13: - | F13: - | G13: - | H13: - | I13: - | J13: - | K13: - | L13: - | M13: -

Sheet Охрана
A2: Терминал | B2: Локация
B3: Москва | D3: СПб | F3: Новосибирск | H3: Екатеринбург
B4: Москва | C4: Москва | D4: СПб | E4: СПб | F4: Новосибирск | G4: Новосибирск | H4: Екатеринбург | I4: Екатеринбург
B5: 20 | C5: 40 | D5: 20 | E5: 40 | F5: 20 | G5: 40 | H5: 20 | I5: 40
A6: ВСК | B6: 3394 | C6: 6801 | D6: 3394 | E6: 6801 | F6: 2140 | G6: 4427 | H6: 2439 | I6: 4939
A7: ВМТП | B7: 3822 | C7: 6910 | D7: 4144 | E7: 7551 | F7: 2740 | G7: 4829 | H7: 3189 | I7: 5689
A8: ВМКТ | B8: 4100 | C8: 8200 | D8: 4100 | E8: 8200 | F8: 2400 | G8: 4900 | H8: 3000 | I8: 6000
A9: ВМПП | B9: 3394 | C9: 6801 | D9: 3394 | E9: 6801 | F9: 1990 | G9: 4079 | H9: 2439 | I9: 4939
A10: СОЛЛЕРС | B10: 3394 | C10: 6801 | D10: 3394 | E10: 6801 | F10: 1990 | G10: 4079 | H10: 2439 | I10: 4939
A11: ВМТП (Феско) | B11: 3822 | C11: 6910 | D11: 4144 | E11: 7551 | F11: 2740 | G11: 4829 | H11: 3189 | I11: 5689
A12: ВМТП (Феско ост.) | B12: 3822 | C12: 6910 | D12: 4144 | E12: 7551 | F12: 2740 | G12: 4829 | H12: 3189 | I12: 5689

Sheet Москва
A1: POL | B1: POL | C1: Экспедитор | D1: Терминал ДВ | E1: Фрахт | G1: дроп-офф | I1: жд тариф | L1: Итого | O1: ВОХР | R1: Курс | S1: 60
E2: 20 | F2: 40 | G2: 20 | H2: 40 | I2: 20<24т | J2: 20<28т | K2: 40 | L2: 20<24т | M2: 20<28т | N2: 40 | O2: 20 | P2: 40 | R2: Имя листа | S2: {=_xlfn.TEXTAFTER(CELL("filename", A1), "]")} -> Москва
A3: NINGBO | B3: NINGBO | C3: Трансконтейнер (Сквозной сервис) | D3: ВСК (ТК) Ningbo | E3: {=IFERROR(_xlfn.XLOOKUP(1, (Фрахт!$A$5:$A$80 = $A3)* (Фрахт!$B$5:$B$80 = $C3) * (Фрахт!$C$5:$C$80 =$D3), _xlfn.XLOOKUP(1, (Фрахт!$D$4:$E$4 = E$2) * 1, Фрахт!$D$5:$E$80)) * $S$1, "-")} -> - | F3: {=IFERROR(_xlfn.XLOOKUP(1, (Фрахт!$A$5:$A$80 = $A3)* (Фрахт!$B$5:$B$80 = $C3) * (Фрахт!$C$5:$C$80 =$D3), _xlfn.XLOOKUP(1, (Фрахт!$D$4:$E$4 = F$2) * 1, Фрахт!$D$5:$E$80)) * $S$1, "-")} -> - | G3: {=IFERROR(_xlfn.XLOOKUP(1, ('Drop off'!$A$6:$A$14 = $C3) * 1, _xlfn.XLOOKUP(1, ('Drop off'!$B$5:$I$5 = G$2) * ('Drop off'!$B$4:$I$4 = $S$2), 'Drop off'!$B$6:$I$14)) * $S$1, "-")} -> 0 | H3: {=IFERROR(_xlfn.XLOOKUP(1, ('Drop off'!$A$6:$A$14 = $C3) * 1, _xlfn.XLOOKUP(1, ('Drop off'!$B$5:$I$5 = H$2) * ('Drop off'!$B$4:$I$4 = $S$2), 'Drop off'!$B$6:$I$14)) * $S$1, "-")} -> 0 | I3: {=IFERROR(_xlfn.XLOOKUP(1, ('ж.д.'!$A$6:$A$14 = $D3) * 1, _xlfn.XLOOKUP(1, ('ж.д.'!$B$5:$M$5 = I$2) * ('ж.д.'!$B$4:$M$4 = $S$2), 'ж.д.'!$B$6:$M$14)), "-")} -> - | J3: {=IFERROR(_xlfn.XLOOKUP(1, ('ж.д.'!$A$6:$A$14 = $D3) * 1, _xlfn.XLOOKUP(1, ('ж.д.'!$B$5:$M$5 = J$2) * ('ж.д.'!$B$4:$M$4 = $S$2), 'ж.д.'!$B$6:$M$14)), "-")} -> - | K3: {=IFERROR(_xlfn.XLOOKUP(1, ('ж.д.'!$A$6:$A$14 = $D3) * 1, _xlfn.XLOOKUP(1, ('ж.д.'!$B$5:$M$5 = K$2) * ('ж.д.'!$B$4:$M$4 = $S$2), 'ж.д.'!$B$6:$M$14)), "-")} -> - | L3: {=IF(ISNUMBER(SEARCH("Транс",$C3)),_xlfn.XLOOKUP(1,('Фрахт Транс'!$A$5:$A$10=$D3)*1,_xlfn.XLOOKUP(1,('Фрахт Транс'!$B$3:$M$3 = $S$2)*('Фрахт Транс'!$B$4:$M$4=L$2),'Фрахт Транс'!$B$5:$M$10)),SUM($E3, $G3, $I3, $O3))} -> 354626 | M3: {=IF(ISNUMBER(SEARCH("Транс",$C3)),_xlfn.XLOOKUP(1,('Фрахт Транс'!$A$5:$A$10=$D3)*1,_xlfn.XLOOKUP(1,('Фрахт Транс'!$B$3:$M$3=$S$2)*('Фрахт Транс'!$B$4:$M$4=M$2),'Фрахт Транс'!$B$5:$M$10)),SUM($E3, $G3, $J3, $O3))} -> 372164 | N3: {=IF(ISNUMBER(SEARCH("Транс",$C3)),_xlfn.XLOOKUP(1,('Фрахт Транс'!$A$5:$A$10=$D3)*1,_xlfn.XLOOKUP(1,('Фрахт Транс'!$B$3:$M$3=$S$2)*('Фрахт Транс'!$B$4:$M$4=N$2),'Фрахт Транс'!$B$5:$M$10)),SUM($F3, $H3, $K3, $P3))} -> 566328 | O3: {=IFERROR(_xlfn.XLOOKUP(1, (Охрана!$A$6:$A$14 = $D3) * 1, _xlfn.XLOOKUP(1, (Охрана!$B$5:$M$5 = O$2) * (Охрана!$B$4:$M$4 = $S$2), Охрана!$B$6:$M$14)), "-")} -> - | P3: {=IFERROR(_xlfn.XLOOKUP(1, (Охрана!$A$6:$A$14 = $D3) * 1, _xlfn.XLOOKUP(1, (Охрана!$B$5:$M$5 = P$2) * (Охрана!$B$4:$M$4 = $S$2), Охрана!$B$6:$M$14)), "-")} -> -
A4: NINGBO | C4: ФЕСКО | D4: ВМТП (Феско) | E4: {=IFERROR(_xlfn.XLOOKUP(1, (Фрахт!$A$5:$A$80 = $A4)* (Фрахт!$B$5:$B$80 = $C4) * (Фрахт!$C$5:$C$80 =$D4), _xlfn.XLOOKUP(1, (Фрахт!$D$4:$E$4 = E$2) * 1, Фрахт!$D$5:$E$80)) * $S$1, "-")} -> 330000 | F4: {=IFERROR(_xlfn.XLOOKUP(1, (Фрахт!$A$5:$A$80 = $A4)* (Фрахт!$B$5:$B$80 = $C4) * (Фрахт!$C$5:$C$80 =$D4), _xlfn.XLOOKUP(1, (Фрахт!$D$4:$E$4 = F$2) * 1, Фрахт!$D$5:$E$80)) * $S$1, "-")} -> 450000 | G4: {=IFERROR(_xlfn.XLOOKUP(1, ('Drop off'!$A$6:$A$14 = $C4) * 1, _xlfn.XLOOKUP(1, ('Drop off'!$B$5:$I$5 = G$2) * ('Drop off'!$B$4:$I$4 = $S$2), 'Drop off'!$B$6:$I$14)) * $S$1, "-")} -> 0 | H4: {=IFERROR(_xlfn.XLOOKUP(1, ('Drop off'!$A$6:$A$14 = $C4) * 1, _xlfn.XLOOKUP(1, ('Drop off'!$B$5:$I$5 = H$2) * ('Drop off'!$B$4:$I$4 = $S$2), 'Drop off'!$B$6:$I$14)) * $S$1, "-")} -> 0 | I4: {=IFERROR(_xlfn.XLOOKUP(1, ('ж.д.'!$A$6:$A$14 = $D4) * 1, _xlfn.XLOOKUP(1, ('ж.д.'!$B$5:$M$5 = I$2) * ('ж.д.'!$B$4:$M$4 = $S$2), 'ж.д.'!$B$6:$M$14)), "-")} -> 167600 | J4: {=IFERROR(_xlfn.XLOOKUP(1, ('ж.д.'!$A$6:$A$14 = $D4) * 1, _xlfn.XLOOKUP(1, ('ж.д.'!$B$5:$M$5 = J$2) * ('ж.д.'!$B$4:$M$4 = $S$2), 'ж.д.'!$B$6:$M$14)), "-")} -> 181540 | K4: {=IFERROR(_xlfn.XLOOKUP(1, ('ж.д.'!$A$6:$A$14 = $D4) * 1, _xlfn.XLOOKUP(1, ('ж.д.'!$B$5:$M$5 = K$2) * ('ж.д.'!$B$4:$M$4 = $S$2), 'ж.д.'!$B$6:$M$14)), "-")} -> 292000 | L4: {=IF(ISNUMBER(SEARCH("Транс",$C4)),_xlfn.XLOOKUP(1,('Фрахт Транс'!$A$5:$A$10=$D4)*1,_xlfn.XLOOKUP(1,('Фрахт Транс'!$B$3:$M$3 = $S$2)*('Фрахт Транс'!$B$4:$M$4=L$2),'Фрахт Транс'!$B$5:$M$10)),SUM($E4, $G4, $I4, $O4))} -> 501422 | M4: {=IF(ISNUMBER(SEARCH("Транс",$C4)),_xlfn.XLOOKUP(1,('Фрахт Транс'!$A$5:$A$10=$D4)*1,_xlfn.XLOOKUP(1,('Фрахт Транс'!$B$3:$M$3=$S$2)*('Фрахт Транс'!$B$4:$M$4=M$2),'Фрахт Транс'!$B$5:$M$10)),SUM($E4, $G4, $J4, $O4))} -> 515362 | N4: {=IF(ISNUMBER(SEARCH("Транс",$C4)),_xlfn.XLOOKUP(1,('Фрахт Транс'!$A$5:$A$10=$D4)*1,_xlfn.XLOOKUP(1,('Фрахт Транс'!$B$3:$M$3=$S$2)*('Фрахт Транс'!$B$4:$M$4=N$2),'Фрахт Транс'!$B$5:$M$10)),SUM($F4, $H4, $K4, $P4))} -> 748910 | O4: {=IFERROR(_xlfn.XLOOKUP(1, (Охрана!$A$6:$A$14 = $D4) * 1, _xlfn.XLOOKUP(1, (Охрана!$B$5:$M$5 = O$2) * (Охрана!$B$4:$M$4 = $S$2), Охрана!$B$6:$M$14)), "-")} -> 3822 | P4: {=IFERROR(_xlfn.XLOOKUP(1, (Охрана!$A$6:$A$14 = $D4) * 1, _xlfn.XLOOKUP(1, (Охрана!$B$5:$M$5 = P$2) * (Охрана!$B$4:$M$4 = $S$2), Охрана!$B$6:$M$14)), "-")} -> 6910
A5: NINGBO | C5: ФЕСКО | D5: ВМТП (Феско ост.) | E5: {=IFERROR(_xlfn.XLOOKUP(1, (Фрахт!$A$5:$A$80 = $A5)* (Фрахт!$B$5:$B$80 = $C5) * (Фрахт!$C$5:$C$80 =$D5), _xlfn.XLOOKUP(1, (Фрахт!$D$4:$E$4 = E$2) * 1, Фрахт!$D$5:$E$80)) * $S$1, "-")} -> 330000 | F5: {=IFERROR(_xlfn.XLOOKUP(1, (Фрахт!$A$5:$A$80 = $A5)* (Фрахт!$B$5:$B$80 = $C5) * (Фрахт!$C$5:$C$80 =$D5), _xlfn.XLOOKUP(1, (Фрахт!$D$4:$E$4 = F$2) * 1, Фрахт!$D$5:$E$80)) * $S$1, "-")} -> 450000 | G5: {=IFERROR(_xlfn.XLOOKUP(1, ('Drop off'!$A$6:$A$14 = $C5) * 1, _xlfn.XLOOKUP(1, ('Drop off'!$B$5:$I$5 = G$2) * ('Drop off'!$B$4:$I$4 = $S$2), 'Drop off'!$B$6:$I$14)) * $S$1, "-")} -> 0 | H5: {=IFERROR(_xlfn.XLOOKUP(1, ('Drop off'!$A$6:$A$14 = $C5) * 1, _xlfn.XLOOKUP(1, ('Drop off'!$B$5:$I$5 = H$2) * ('Drop off'!$B$4:$I$4 = $S$2), 'Drop off'!$B$6:$I$14)) * $S$1, "-")} -> 0 | I5: {=IFERROR(_xlfn.XLOOKUP(1, ('ж.д.'!$A$6:$A$14 = $D5) * 1, _xlfn.XLOOKUP(1, ('ж.д.'!$B$5:$M$5 = I$2) * ('ж.д.'!$B$4:$M$4 = $S$2), 'ж.д.'!$B$6:$M$14)), "-")} -> 173730 | J5: {=IFERROR(_xlfn.XLOOKUP(1, ('ж.д.'!$A$6:$A$14 = $D5) * 1, _xlfn.XLOOKUP(1, ('ж.д.'!$B$5:$M$5 = J$2) * ('ж.д.'!$B$4:$M$4 = $S$2), 'ж.д.'!$B$6:$M$14)), "-")} -> 191045 | K5: {=IFERROR(_xlfn.XLOOKUP(1, ('ж.д.'!$A$6:$A$14 = $D5) * 1, _xlfn.XLOOKUP(1, ('ж.д.'!$B$5:$M$5 = K$2) * ('ж.д.'!$B$4:$M$4 = $S$2), 'ж.д.'!$B$6:$M$14)), "-")} -> 303815 | L5: {=IF(ISNUMBER(SEARCH("Транс",$C5)),_xlfn.XLOOKUP(1,('Фрахт Транс'!$A$5:$A$10=$D5)*1,_xlfn.XLOOKUP(1,('Фрахт Транс'!$B$3:$M$3 = $S$2)*('Фрахт Транс'!$B$4:$M$4=L$2),'Фрахт Транс'!$B$5:$M$10)),SUM($E5, $G5, $I5, $O5))} -> 507552 | M5: {=IF(ISNUMBER(SEARCH("Транс",$C5)),_xlfn.XLOOKUP(1,('Фрахт Транс'!$A$5:$A$10=$D5)*1,_xlfn.XLOOKUP(1,('Фрахт Транс'!$B$3:$M$3=$S$2)*('Фрахт Транс'!$B$4:$M$4=M$2),'Фрахт Транс'!$B$5:$M$10)),SUM($E5, $G5, $J5, $O5))} -> 524867 | N5: {=IF(ISNUMBER(SEARCH("Транс",$C5)),_xlfn.XLOOKUP(1,('Фрахт Транс'!$A$5:$A$10=$D5)*1,_xlfn.XLOOKUP(1,('Фрахт Транс'!$B$3:$M$3=$S$2)*('Фрахт Транс'!$B$4:$M$4=N$2),'Фрахт Транс'!$B$5:$M$10)),SUM($F5, $H5, $K5, $P5))} -> 760725 | O5: {=IFERROR(_xlfn.XLOOKUP(1, (Охрана!$A$6:$A$14 = $D5) * 1, _xlfn.XLOOKUP(1, (Охрана!$B$5:$M$5 = O$2) * (Охрана!$B$4:$M$4 = $S$2), Охрана!$B$6:$M$14)), "-")} -> 3822 | P5: {=IFERROR(_xlfn.XLOOKUP(1, (Охрана!$A$6:$A$14 = $D5) * 1, _xlfn.XLOOKUP(1, (Охрана!$B$5:$M$5 = P$2) * (Охрана!$B$4:$M$4 = $S$2), Охрана!$B$6:$M$14)), "-")} -> 6910
A6: NINGBO | C6: SINOKOR | D6: ВСК | E6: {=IFERROR(_xlfn.XLOOKUP(1, (Фрахт!$A$5:$A$80 = $A6)* (Фрахт!$B$5:$B$80 = $C6) * (Фрахт!$C$5:$C$80 =$D6), _xlfn.XLOOKUP(1, (Фрахт!$D$4:$E$4 = E$2) * 1, Фрахт!$D$5:$E$80)) * $S$1, "-")} -> 283500 | F6: {=IFERROR(_xlfn.XLOOKUP(1, (Фрахт!$A$5:$A$80 = $A6)* (Фрахт!$B$5:$B$80 = $C6) * (Фрахт!$C$5:$C$80 =$D6), _xlfn.XLOOKUP(1, (Фрахт!$D$4:$E$4 = F$2) * 1, Фрахт!$D$5:$E$80)) * $S$1, "-")} -> 472500 | G6: {=IFERROR(_xlfn.XLOOKUP(1, ('Drop off'!$A$6:$A$14 = $C6) * 1, _xlfn.XLOOKUP(1, ('Drop off'!$B$5:$I$5 = G$2) * ('Drop off'!$B$4:$I$4 = $S$2), 'Drop off'!$B$6:$I$14)) * $S$1, "-")} -> 56700 | H6: {=IFERROR(_xlfn.XLOOKUP(1, ('Drop off'!$A$6:$A$14 = $C6) * 1, _xlfn.XLOOKUP(1, ('Drop off'!$B$5:$I$5 = H$2) * ('Drop off'!$B$4:$I$4 = $S$2), 'Drop off'!$B$6:$I$14)) * $S$1, "-")} -> 37800 | I6: {=IFERROR(_xlfn.XLOOKUP(1, ('ж.д.'!$A$6:$A$14 = $D6) * 1, _xlfn.XLOOKUP(1, ('ж.д.'!$B$5:$M$5 = I$2) * ('ж.д.'!$B$4:$M$4 = $S$2), 'ж.д.'!$B$6:$M$14)), "-")} -> 122400 | J6: {=IFERROR(_xlfn.XLOOKUP(1, ('ж.д.'!$A$6:$A$14 = $D6) * 1, _xlfn.XLOOKUP(1, ('ж.д.'!$B$5:$M$5 = J$2) * ('ж.д.'!$B$4:$M$4 = $S$2), 'ж.д.'!$B$6:$M$14)), "-")} -> 139800 | K6: {=IFERROR(_xlfn.XLOOKUP(1, ('ж.д.'!$A$6:$A$14 = $D6) * 1, _xlfn.XLOOKUP(1, ('ж.д.'!$B$5:$M$5 = K$2) * ('ж.д.'!$B$4:$M$4 = $S$2), 'ж.д.'!$B$6:$M$14)), "-")} -> 224600 | L6: {=IF(ISNUMBER(SEARCH("Транс",$C6)),_xlfn.XLOOKUP(1,('Фрахт Транс'!$A$5:$A$10=$D6)*1,_xlfn.XLOOKUP(1,('Фрахт Транс'!$B$3:$M$3 = $S$2)*('Фрахт Транс'!$B$4:$M$4=L$2),'Фрахт Транс'!$B$5:$M$10)),SUM($E6, $G6, $I6, $O6))} -> 465994 | M6: {=IF(ISNUMBER(SEARCH("Транс",$C6)),_xlfn.XLOOKUP(1,('Фрахт Транс'!$A$5:$A$10=$D6)*1,_xlfn.XLOOKUP(1,('Фрахт Транс'!$B$3:$M$3=$S$2)*('Фрахт Транс'!$B$4:$M$4=M$2),'Фрахт Транс'!$B$5:$M$10)),SUM($E6, $G6, $J6, $O6))} -> 483394 | N6: {=IF(ISNUMBER(SEARCH("Транс",$C6)),_xlfn.XLOOKUP(1,('Фрахт Транс'!$A$5:$A$10=$D6)*1,_xlfn.XLOOKUP(1,('Фрахт Транс'!$B$3:$M$3=$S$2)*('Фрахт Транс'!$B$4:$M$4=N$2),'Фрахт Транс'!$B$5:$M$10)),SUM($F6, $H6, $K6, $P6))} -> 741701 | O6: {=IFERROR(_xlfn.XLOOKUP(1, (Охрана!$A$6:$A$14 = $D6) * 1, _xlfn.XLOOKUP(1, (Охрана!$B$5:$M$5 = O$2) * (Охрана!$B$4:$M$4 = $S$2), Охрана!$B$6:$M$14)), "-")} -> 3394 | P6: {=IFERROR(_xlfn.XLOOKUP(1, (Охрана!$A$6:$A$14 = $D6) * 1, _xlfn.XLOOKUP(1, (Охрана!$B$5:$M$5 = P$2) * (Охрана!$B$4:$M$4 = $S$2), Охрана!$B$6:$M$14)), "-")} -> 6801
A7: NINGBO | C7: SINOKOR | D7: Соллерс | E7: {=IFERROR(_xlfn.XLOOKUP(1, (Фрахт!$A$5:$A$80 = $A7)* (Фрахт!$B$5:$B$80 = $C7) * (Фрахт!$C$5:$C$80 =$D7), _xlfn.XLOOKUP(1, (Фрахт!$D$4:$E$4 = E$2) * 1, Фрахт!$D$5:$E$80)) * $S$1, "-")} -> 283500 | F7: {=IFERROR(_xlfn.XLOOKUP(1, (Фрахт!$A$5:$A$80 = $A7)* (Фрахт!$B$5:$B$80 = $C7) * (Фрахт!$C$5:$C$80 =$D7), _xlfn.XLOOKUP(1, (Фрахт!$D$4:$E$4 = F$2) * 1, Фрахт!$D$5:$E$80)) * $S$1, "-")} -> 472500 | G7: {=IFERROR(_xlfn.XLOOKUP(1, ('Drop off'!$A$6:$A$14 = $C7) * 1, _xlfn.XLOOKUP(1, ('Drop off'!$B$5:$I$5 = G$2) * ('Drop off'!$B$4:$I$4 = $S$2), 'Drop off'!$B$6:$I$14)) * $S$1, "-")} -> 56700 | H7: {=IFERROR(_xlfn.XLOOKUP(1, ('Drop off'!$A$6:$A$14 = $C7) * 1, _xlfn.XLOOKUP(1, ('Drop off'!$B$5:$I$5 = H$2) * ('Drop off'!$B$4:$I$4 = $S$2), 'Drop off'!$B$6:$I$14)) * $S$1, "-")} -> 37800 | I7: {=IFERROR(_xlfn.XLOOKUP(1, ('ж.д.'!$A$6:$A$14 = $D7) * 1, _xlfn.XLOOKUP(1, ('ж.д.'!$B$5:$M$5 = I$2) * ('ж.д.'!$B$4:$M$4 = $S$2), 'ж.д.'!$B$6:$M$14)), "-")} -> 134400 | J7: {=IFERROR(_xlfn.XLOOKUP(1, ('ж.д.'!$A$6:$A$14 = $D7) * 1, _xlfn.XLOOKUP(1, ('ж.д.'!$B$5:$M$5 = J$2) * ('ж.д.'!$B$4:$M$4 = $S$2), 'ж.д.'!$B$6:$M$14)), "-")} -> 149400 | K7: {=IFERROR(_xlfn.XLOOKUP(1, ('ж.д.'!$A$6:$A$14 = $D7) * 1, _xlfn.XLOOKUP(1, ('ж.д.'!$B$5:$M$5 = K$2) * ('ж.д.'!$B$4:$M$4 = $S$2), 'ж.д.'!$B$6:$M$14)), "-")} -> 235000 | L7: {=IF(ISNUMBER(SEARCH("Транс",$C7)),_xlfn.XLOOKUP(1,('Фрахт Транс'!$A$5:$A$10=$D7)*1,_xlfn.XLOOKUP(1,('Фрахт Транс'!$B$3:$M$3 = $S$2)*('Фрахт Транс'!$B$4:$M$4=L$2),'Фрахт Транс'!$B$5:$M$10)),SUM($E7, $G7, $I7, $O7))} -> 477994 | M7: {=IF(ISNUMBER(SEARCH("Транс",$C7)),_xlfn.XLOOKUP(1,('Фрахт Транс'!$A$5:$A$10=$D7)*1,_xlfn.XLOOKUP(1,('Фрахт Транс'!$B$3:$M$3=$S$2)*('Фрахт Транс'!$B$4:$M$4=M$2),'Фрахт Транс'!$B$5:$M$10)),SUM($E7, $G7, $J7, $O7))} -> 492994 | N7: {=IF(ISNUMBER(SEARCH("Транс",$C7)),_xlfn.XLOOKUP(1,('Фрахт Транс'!$A$5:$A$10=$D7)*1,_xlfn.XLOOKUP(1,('Фрахт Транс'!$B$3:$M$3=$S$2)*('Фрахт Транс'!$B$4:$M$4=N$2),'Фрахт Транс'!$B$5:$M$10)),SUM($F7, $H7, $K7, $P7))} -> 752101 | O7: {=IFERROR(_xlfn.XLOOKUP(1, (Охрана!$A$6:$A$14 = $D7) * 1, _xlfn.XLOOKUP(1, (Охрана!$B$5:$M$5 = O$2) * (Охрана!$B$4:$M$4 = $S$2), Охрана!$B$6:$M$14)), "-")} -> 3394 | P7: {=IFERROR(_xlfn.XLOOKUP(1, (Охрана!$A$6:$A$14 = $D7) * 1, _xlfn.XLOOKUP(1, (Охрана!$B$5:$M$5 = P$2) * (Охрана!$B$4:$M$4 = $S$2), Охрана!$B$6:$M$14)), "-")} -> 6801
A8: NINGBO | C8: SINOKOR | D8: ВМТП | E8: {=IFERROR(_xlfn.XLOOKUP(1, (Фрахт!$A$5:$A$80 = $A8)* (Фрахт!$B$5:$B$80 = $C8) * (Фрахт!$C$5:$C$80 =$D8), _xlfn.XLOOKUP(1, (Фрахт!$D$4:$E$4 = E$2) * 1, Фрахт!$D$5:$E$80)) * $S$1, "-")} -> 283500 | F8: {=IFERROR(_xlfn.XLOOKUP(1, (Фрахт!$A$5:$A$80 = $A8)* (Фрахт!$B$5:$B$80 = $C8) * (Фрахт!$C$5:$C$80 =$D8), _xlfn.XLOOKUP(1, (Фрахт!$D$4:$E$4 = F$2) * 1, Фрахт!$D$5:$E$80)) * $S$1, "-")} -> 472500 | G8: {=IFERROR(_xlfn.XLOOKUP(1, ('Drop off'!$A$6:$A$14 = $C8) * 1, _xlfn.XLOOKUP(1, ('Drop off'!$B$5:$I$5 = G$2) * ('Drop off'!$B$4:$I$4 = $S$2), 'Drop off'!$B$6:$I$14)) * $S$1, "-")} -> 56700 | H8: {=IFERROR(_xlfn.XLOOKUP(1, ('Drop off'!$A$6:$A$14 = $C8) * 1, _xlfn.XLOOKUP(1, ('Drop off'!$B$5:$I$5 = H$2) * ('Drop off'!$B$4:$I$4 = $S$2), 'Drop off'!$B$6:$I$14)) * $S$1, "-")} -> 37800 | I8: {=IFERROR(_xlfn.XLOOKUP(1, ('ж.д.'!$A$6:$A$14 = $D8) * 1, _xlfn.XLOOKUP(1, ('ж.д.'!$B$5:$M$5 = I$2) * ('ж.д.'!$B$4:$M$4 = $S$2), 'ж.д.'!$B$6:$M$14)), "-")} -> 141000 | J8: {=IFERROR(_xlfn.XLOOKUP(1, ('ж.д.'!$A$6:$A$14 = $D8) * 1, _xlfn.XLOOKUP(1, ('ж.д.'!$B$5:$M$5 = J$2) * ('ж.д.'!$B$4:$M$4 = $S$2), 'ж.д.'!$B$6:$M$14)), "-")} -> 156600 | K8: {=IFERROR(_xlfn.XLOOKUP(1, ('ж.д.'!$A$6:$A$14 = $D8) * 1, _xlfn.XLOOKUP(1, ('ж.д.'!$B$5:$M$5 = K$2) * ('ж.д.'!$B$4:$M$4 = $S$2), 'ж.д.'!$B$6:$M$14)), "-")} -> 261000 | L8: {=IF(ISNUMBER(SEARCH("Транс",$C8)),_xlfn.XLOOKUP(1,('Фрахт Транс'!$A$5:$A$10=$D8)*1,_xlfn.XLOOKUP(1,('Фрахт Транс'!$B$3:$M$3 = $S$2)*('Фрахт Транс'!$B$4:$M$4=L$2),'Фрахт Транс'!$B$5:$M$10)),SUM($E8, $G8, $I8, $O8))} -> 485022 | M8: {=IF(ISNUMBER(SEARCH("Транс",$C8)),_xlfn.XLOOKUP(1,('Фрахт Транс'!$A$5:$A$10=$D8)*1,_xlfn.XLOOKUP(1,('Фрахт Транс'!$B$3:$M$3=$S$2)*('Фрахт Транс'!$B$4:$M$4=M$2),'Фрахт Транс'!$B$5:$M$10)),SUM($E8, $G8, $J8, $O8))} -> 500622 | N8: {=IF(ISNUMBER(SEARCH("Транс",$C8)),_xlfn.XLOOKUP(1,('Фрахт Транс'!$A$5:$A$10=$D8)*1,_xlfn.XLOOKUP(1,('Фрахт Транс'!$B$3:$M$3=$S$2)*('Фрахт Транс'!$B$4:$M$4=N$2),'Фрахт Транс'!$B$5:$M$10)),SUM($F8, $H8, $K8, $P8))} -> 778210 | O8: {=IFERROR(_xlfn.XLOOKUP(1, (Охрана!$A$6:$A$14 = $D8) * 1, _xlfn.XLOOKUP(1, (Охрана!$B$5:$M$5 = O$2) * (Охрана!$B$4:$M$4 = $S$2), Охрана!$B$6:$M$14)), "-")} -> 3822 | P8: {=IFERROR(_xlfn.XLOOKUP(1, (Охрана!$A$6:$A$14 = $D8) * 1, _xlfn.XLOOKUP(1, (Охрана!$B$5:$M$5 = P$2) * (Охрана!$B$4:$M$4 = $S$2), Охрана!$B$6:$M$14)), "-")} -> 6910
A9: NINGBO | C9: SINOKOR | D9: ВМКТ | E9: {=IFERROR(_xlfn.XLOOKUP(1, (Фрахт!$A$5:$A$80 = $A9)* (Фрахт!$B$5:$B$80 = $C9) * (Фрахт!$C$5:$C$80 =$D9), _xlfn.XLOOKUP(1, (Фрахт!$D$4:$E$4 = E$2) * 1, Фрахт!$D$5:$E$80)) * $S$1, "-")} -> 283500 | F9: {=IFERROR(_xlfn.XLOOKUP(1, (Фрахт!$A$5:$A$80 = $A9)* (Фрахт!$B$5:$B$80 = $C9) * (Фрахт!$C$5:$C$80 =$D9), _xlfn.XLOOKUP(1, (Фрахт!$D$4:$E$4 = F$2) * 1, Фрахт!$D$5:$E$80)) * $S$1, "-")} -> 472500 | G9: {=IFERROR(_xlfn.XLOOKUP(1, ('Drop off'!$A$6:$A$14 = $C9) * 1, _xlfn.XLOOKUP(1, ('Drop off'!$B$5:$I$5 = G$2) * ('Drop off'!$B$4:$I$4 = $S$2), 'Drop off'!$B$6:$I$14)) * $S$1, "-")} -> 56700 | H9: {=IFERROR(_xlfn.XLOOKUP(1, ('Drop off'!$A$6:$A$14 = $C9) * 1, _xlfn.XLOOKUP(1, ('Drop off'!$B$5:$I$5 = H$2) * ('Drop off'!$B$4:$I$4 = $S$2), 'Drop off'!$B$6:$I$14)) * $S$1, "-")} -> 37800 | I9: {=IFERROR(_xlfn.XLOOKUP(1, ('ж.д.'!$A$6:$A$14 = $D9) * 1, _xlfn.XLOOKUP(1, ('ж.д.'!$B$5:$M$5 = I$2) * ('ж.д.'!$B$4:$M$4 = $S$2), 'ж.д.'!$B$6:$M$14)), "-")} -> 125000 | J9: {=IFERROR(_xlfn.XLOOKUP(1, ('ж.д.'!$A$6:$A$14 = $D9) * 1, _xlfn.XLOOKUP(1, ('ж.д.'!$B$5:$M$5 = J$2) * ('ж.д.'!$B$4:$M$4 = $S$2), 'ж.д.'!$B$6:$M$14)), "-")} -> 140000 | K9: {=IFERROR(_xlfn.XLOOKUP(1, ('ж.д.'!$A$6:$A$14 = $D9) * 1, _xlfn.XLOOKUP(1, ('ж.д.'!$B$5:$M$5 = K$2) * ('ж.д.'!$B$4:$M$4 = $S$2), 'ж.д.'!$B$6:$M$14)), "-")} -> 227000 | L9: {=IF(ISNUMBER(SEARCH("Транс",$C9)),_xlfn.XLOOKUP(1,('Фрахт Транс'!$A$5:$A$10=$D9)*1,_xlfn.XLOOKUP(1,('Фрахт Транс'!$B$3:$M$3 = $S$2)*('Фрахт Транс'!$B$4:$M$4=L$2),'Фрахт Транс'!$B$5:$M$10)),SUM($E9, $G9, $I9, $O9))} -> 469300 | M9: {=IF(ISNUMBER(SEARCH("Транс",$C9)),_xlfn.XLOOKUP(1,('Фрахт Транс'!$A$5:$A$10=$D9)*1,_xlfn.XLOOKUP(1,('Фрахт Транс'!$B$3:$M$3=$S$2)*('Фрахт Транс'!$B$4:$M$4=M$2),'Фрахт Транс'!$B$5:$M$10)),SUM($E9, $G9, $J9, $O9))} -> 484300 | N9: {=IF(ISNUMBER(SEARCH("Транс",$C9)),_xlfn.XLOOKUP(1,('Фрахт Транс'!$A$5:$A$10=$D9)*1,_xlfn.XLOOKUP(1,('Фрахт Транс'!$B$3:$M$3=$S$2)*('Фрахт Транс'!$B$4:$M$4=N$2),'Фрахт Транс'!$B$5:$M$10)),SUM($F9, $H9, $K9, $P9))} -> 745500 | O9: {=IFERROR(_xlfn.XLOOKUP(1, (Охрана!$A$6:$A$14 = $D9) * 1, _xlfn.XLOOKUP(1, (Охрана!$B$5:$M$5 = O$2) * (Охрана!$B$4:$M$4 = $S$2), Охрана!$B$6:$M$14)), "-")} -> 4100 | P9: {=IFERROR(_xlfn.XLOOKUP(1, (Охрана!$A$6:$A$14 = $D9) * 1, _xlfn.XLOOKUP(1, (Охрана!$B$5:$M$5 = P$2) * (Охрана!$B$4:$M$4 = $S$2), Охрана!$B$6:$M$14)), "-")} -> 8200
A10: NINGBO | C10: HUAXIN | D10: СОЛЛЕРС | E10: {=IFERROR(_xlfn.XLOOKUP(1, (Фрахт!$A$5:$A$80 = $A10)* (Фрахт!$B$5:$B$80 = $C10) * (Фрахт!$C$5:$C$80 =$D10), _xlfn.XLOOKUP(1, (Фрахт!$D$4:$E$4 = E$2) * 1, Фрахт!$D$5:$E$80)) * $S$1, "-")} -> 260160 | F10: {=IFERROR(_xlfn.XLOOKUP(1, (Фрахт!$A$5:$A$80 = $A10)* (Фрахт!$B$5:$B$80 = $C10) * (Фрахт!$C$5:$C$80 =$D10), _xlfn.XLOOKUP(1, (Фрахт!$D$4:$E$4 = F$2) * 1, Фрахт!$D$5:$E$80)) * $S$1, "-")} -> 436320 | G10: {=IFERROR(_xlfn.XLOOKUP(1, ('Drop off'!$A$6:$A$14 = $C10) * 1, _xlfn.XLOOKUP(1, ('Drop off'!$B$5:$I$5 = G$2) * ('Drop off'!$B$4:$I$4 = $S$2), 'Drop off'!$B$6:$I$14)) * $S$1, "-")} -> 42000 | H10: {=IFERROR(_xlfn.XLOOKUP(1, ('Drop off'!$A$6:$A$14 = $C10) * 1, _xlfn.XLOOKUP(1, ('Drop off'!$B$5:$I$5 = H$2) * ('Drop off'!$B$4:$I$4 = $S$2), 'Drop off'!$B$6:$I$14)) * $S$1, "-")} -> 42000 | I10: {=IFERROR(_xlfn.XLOOKUP(1, ('ж.д.'!$A$6:$A$14 = $D10) * 1, _xlfn.XLOOKUP(1, ('ж.д.'!$B$5:$M$5 = I$2) * ('ж.д.'!$B$4:$M$4 = $S$2), 'ж.д.'!$B$6:$M$14)), "-")} -> 134400 | J10: {=IFERROR(_xlfn.XLOOKUP(1, ('ж.д.'!$A$6:$A$14 = $D10) * 1, _xlfn.XLOOKUP(1, ('ж.д.'!$B$5:$M$5 = J$2) * ('ж.д.'!$B$4:$M$4 = $S$2), 'ж.д.'!$B$6:$M$14)), "-")} -> 149400 | K10: {=IFERROR(_xlfn.XLOOKUP(1, ('ж.д.'!$A$6:$A$14 = $D10) * 1, _xlfn.XLOOKUP(1, ('ж.д.'!$B$5:$M$5 = K$2) * ('ж.д.'!$B$4:$M$4 = $S$2), 'ж.д.'!$B$6:$M$14)), "-")} -> 235000 | L10: {=IF(ISNUMBER(SEARCH("Транс",$C10)),_xlfn.XLOOKUP(1,('Фрахт Транс'!$A$5:$A$10=$D10)*1,_xlfn.XLOOKUP(1,('Фрахт Транс'!$B$3:$M$3 = $S$2)*('Фрахт Транс'!$B$4:$M$4=L$2),'Фрахт Транс'!$B$5:$M$10)),SUM($E10, $G10, $I10, $O10))} -> 439954 | M10: {=IF(ISNUMBER(SEARCH("Транс",$C10)),_xlfn.XLOOKUP(1,('Фрахт Транс'!$A$5:$A$10=$D10)*1,_xlfn.XLOOKUP(1,('Фрахт Транс'!$B$3:$M$3=$S$2)*('Фрахт Транс'!$B$4:$M$4=M$2),'Фрахт Транс'!$B$5:$M$10)),SUM($E10, $G10, $J10, $O10))} -> 454954 | N10: {=IF(ISNUMBER(SEARCH("Транс",$C10)),_xlfn.XLOOKUP(1,('Фрахт Транс'!$A$5:$A$10=$D10)*1,_xlfn.XLOOKUP(1,('Фрахт Транс'!$B$3:$M$3=$S$2)*('Фрахт Транс'!$B$4:$M$4=N$2),'Фрахт Транс'!$B$5:$M$10)),SUM($F10, $H10, $K10, $P10))} -> 720121 | O10: {=IFERROR(_xlfn.XLOOKUP(1, (Охрана!$A$6:$A$14 = $D10) * 1, _xlfn.XLOOKUP(1, (Охрана!$B$5:$M$5 = O$2) * (Охрана!$B$4:$M$4 = $S$2), Охрана!$B$6:$M$14)), "-")} -> 3394 | P10: {=IFERROR(_xlfn.XLOOKUP(1, (Охрана!$A$6:$A$14 = $D10) * 1, _xlfn.XLOOKUP(1, (Охрана!$B$5:$M$5 = P$2) * (Охрана!$B$4:$M$4 = $S$2), Охрана!$B$6:$M$14)), "-")} -> 6801
A11: NINGBO | C11: ТоргМолл | D11: ВСК | E11: {=IFERROR(_xlfn.XLOOKUP(1, (Фрахт!$A$5:$A$80 = $A11)* (Фрахт!$B$5:$B$80 = $C11) * (Фрахт!$C$5:$C$80 =$D11), _xlfn.XLOOKUP(1, (Фрахт!$D$4:$E$4 = E$2) * 1, Фрахт!$D$5:$E$80)) * $S$1, "-")} -> 216000 | F11: {=IFERROR(_xlfn.XLOOKUP(1, (Фрахт!$A$5:$A$80 = $A11)* (Фрахт!$B$5:$B$80 = $C11) * (Фрахт!$C$5:$C$80 =$D11), _xlfn.XLOOKUP(1, (Фрахт!$D$4:$E$4 = F$2) * 1, Фрахт!$D$5:$E$80)) * $S$1, "-")} -> 384000 | G11: {=IFERROR(_xlfn.XLOOKUP(1, ('Drop off'!$A$6:$A$14 = $C11) * 1, _xlfn.XLOOKUP(1, ('Drop off'!$B$5:$I$5 = G$2) * ('Drop off'!$B$4:$I$4 = $S$2), 'Drop off'!$B$6:$I$14)) * $S$1, "-")} -> 0 | H11: {=IFERROR(_xlfn.XLOOKUP(1, ('Drop off'!$A$6:$A$14 = $C11) * 1, _xlfn.XLOOKUP(1, ('Drop off'!$B$5:$I$5 = H$2) * ('Drop off'!$B$4:$I$4 = $S$2), 'Drop off'!$B$6:$I$14)) * $S$1, "-")} -> 0 | I11: {=IFERROR(_xlfn.XLOOKUP(1, ('ж.д.'!$A$6:$A$14 = $D11) * 1, _xlfn.XLOOKUP(1, ('ж.д.'!$B$5:$M$5 = I$2) * ('ж.д.'!$B$4:$M$4 = $S$2), 'ж.д.'!$B$6:$M$14)), "-")} -> 122400 | J11: {=IFERROR(_xlfn.XLOOKUP(1, ('ж.д.'!$A$6:$A$14 = $D11) * 1, _xlfn.XLOOKUP(1, ('ж.д.'!$B$5:$M$5 = J$2) * ('ж.д.'!$B$4:$M$4 = $S$2), 'ж.д.'!$B$6:$M$14)), "-")} -> 139800 | K11: {=IFERROR(_xlfn.XLOOKUP(1, ('ж.д.'!$A$6:$A$14 = $D11) * 1, _xlfn.XLOOKUP(1, ('ж.д.'!$B$5:$M$5 = K$2) * ('ж.д.'!$B$4:$M$4 = $S$2), 'ж.д.'!$B$6:$M$14)), "-")} -> 224600 | L11: {=IF(ISNUMBER(SEARCH("Транс",$C11)),_xlfn.XLOOKUP(1,('Фрахт Транс'!$A$5:$A$10=$D11)*1,_xlfn.XLOOKUP(1,('Фрахт Транс'!$B$3:$M$3 = $S$2)*('Фрахт Транс'!$B$4:$M$4=L$2),'Фрахт Транс'!$B$5:$M$10)),SUM($E11, $G11, $I11, $O11))} -> 341794 | M11: {=IF(ISNUMBER(SEARCH("Транс",$C11)),_xlfn.XLOOKUP(1,('Фрахт Транс'!$A$5:$A$10=$D11)*1,_xlfn.XLOOKUP(1,('Фрахт Транс'!$B$3:$M$3=$S$2)*('Фрахт Транс'!$B$4:$M$4=M$2),'Фрахт Транс'!$B$5:$M$10)),SUM($E11, $G11, $J11, $O11))} -> 359194 | N11: {=IF(ISNUMBER(SEARCH("Транс",$C11)),_xlfn.XLOOKUP(1,('Фрахт Транс'!$A$5:$A$10=$D11)*1,_xlfn.XLOOKUP(1,('Фрахт Транс'!$B$3:$M$3=$S$2)*('Фрахт Транс'!$B$4:$M$4=N$2),'Фрахт Транс'!$B$5:$M$10)),SUM($F11, $H11, $K11, $P11))} -> 615401 | O11: {=IFERROR(_xlfn.XLOOKUP(1, (Охрана!$A$6:$A$14 = $D11) * 1, _xlfn.XLOOKUP(1, (Охрана!$B$5:$M$5 = O$2) * (Охрана!$B$4:$M$4 = $S$2), Охрана!$B$6:$M$14)), "-")} -> 3394 | P11: {=IFERROR(_xlfn.XLOOKUP(1, (Охрана!$A$6:$A$14 = $D11) * 1, _xlfn.XLOOKUP(1, (Охрана!$B$5:$M$5 = P$2) * (Охрана!$B$4:$M$4 = $S$2), Охрана!$B$6:$M$14)), "-")} -> 6801
A12: NINGBO | C12: EuroEast | D12: ВМПП | E12: {=IFERROR(_xlfn.XLOOKUP(1, (Фрахт!$A$5:$A$80 = $A12)* (Фрахт!$B$5:$B$80 = $C12) * (Фрахт!$C$5:$C$80 =$D12), _xlfn.XLOOKUP(1, (Фрахт!$D$4:$E$4 = E$2) * 1, Фрахт!$D$5:$E$80)) * $S$1, "-")} -> - | F12: {=IFERROR(_xlfn.XLOOKUP(1, (Фрахт!$A$5:$A$80 = $A12)* (Фрахт!$B$5:$B$80 = $C12) * (Фрахт!$C$5:$C$80 =$D12), _xlfn.XLOOKUP(1, (Фрахт!$D$4:$E$4 = F$2) * 1, Фрахт!$D$5:$E$80)) * $S$1, "-")} -> - | G12: {=IFERROR(_xlfn.XLOOKUP(1, ('Drop off'!$A$6:$A$14 = $C12) * 1, _xlfn.XLOOKUP(1, ('Drop off'!$B$5:$I$5 = G$2) * ('Drop off'!$B$4:$I$4 = $S$2), 'Drop off'!$B$6:$I$14)) * $S$1, "-")} -> 0 | H12: {=IFERROR(_xlfn.XLOOKUP(1, ('Drop off'!$A$6:$A$14 = $C12) * 1, _xlfn.XLOOKUP(1, ('Drop off'!$B$5:$I$5 = H$2) * ('Drop off'!$B$4:$I$4 = $S$2), 'Drop off'!$B$6:$I$14)) * $S$1, "-")} -> 0 | I12: {=IFERROR(_xlfn.XLOOKUP(1, ('ж.д.'!$A$6:$A$14 = $D12) * 1, _xlfn.XLOOKUP(1, ('ж.д.'!$B$5:$M$5 = I$2) * ('ж.д.'!$B$4:$M$4 = $S$2), 'ж.д.'!$B$6:$M$14)), "-")} -> 134400 | J12: {=IFERROR(_xlfn.XLOOKUP(1, ('ж.д.'!$A$6:$A$14 = $D12) * 1, _xlfn.XLOOKUP(1, ('ж.д.'!$B$5:$M$5 = J$2) * ('ж.д.'!$B$4:$M$4 = $S$2), 'ж.д.'!$B$6:$M$14)), "-")} -> 149400 | K12: {=IFERROR(_xlfn.XLOOKUP(1, ('ж.д.'!$A$6:$A$14 = $D12) * 1, _xlfn.XLOOKUP(1, ('ж.д.'!$B$5:$M$5 = K$2) * ('ж.д.'!$B$4:$M$4 = $S$2), 'ж.д.'!$B$6:$M$14)), "-")} -> 235000 | L12: {=IF(ISNUMBER(SEARCH("Транс",$C12)),_xlfn.XLOOKUP(1,('Фрахт Транс'!$A$5:$A$10=$D12)*1,_xlfn.XLOOKUP(1,('Фрахт Транс'!$B$3:$M$3 = $S$2)*('Фрахт Транс'!$B$4:$M$4=L$2),'Фрахт Транс'!$B$5:$M$10)),SUM($E12, $G12, $I12, $O12))} -> 137794 | M12: {=IF(ISNUMBER(SEARCH("Транс",$C12)),_xlfn.XLOOKUP(1,('Фрахт Транс'!$A$5:$A$10=$D12)*1,_xlfn.XLOOKUP(1,('Фрахт Транс'!$B$3:$M$3=$S$2)*('Фрахт Транс'!$B$4:$M$4=M$2),'Фрахт Транс'!$B$5:$M$10)),SUM($E12, $G12, $J12, $O12))} -> 152794 | N12: {=IF(ISNUMBER(SEARCH("Транс",$C12)),_xlfn.XLOOKUP(1,('Фрахт Транс'!$A$5:$A$10=$D12)*1,_xlfn.XLOOKUP(1,('Фрахт Транс'!$B$3:$M$3=$S$2)*('Фрахт Транс'!$B$4:$M$4=N$2),'Фрахт Транс'!$B$5:$M$10)),SUM($F12, $H12, $K12, $P12))} -> 241801 | O12: {=IFERROR(_xlfn.XLOOKUP(1, (Охрана!$A$6:$A$14 = $D12) * 1, _xlfn.XLOOKUP(1, (Охрана!$B$5:$M$5 = O$2) * (Охрана!$B$4:$M$4 = $S$2), Охрана!$B$6:$M$14)), "-")} -> 3394 | P12: {=IFERROR(_xlfn.XLOOKUP(1, (Охрана!$A$6:$A$14 = $D12) * 1, _xlfn.XLOOKUP(1, (Охрана!$B$5:$M$5 = P$2) * (Охрана!$B$4:$M$4 = $S$2), Охрана!$B$6:$M$14)), "-")} -> 6801
A13: NINGBO | C13: EuroEast | D13: СОЛЛЕРС | E13: {=IFERROR(_xlfn.XLOOKUP(1, (Фрахт!$A$5:$A$80 = $A13)* (Фрахт!$B$5:$B$80 = $C13) * (Фрахт!$C$5:$C$80 =$D13), _xlfn.XLOOKUP(1, (Фрахт!$D$4:$E$4 = E$2) * 1, Фрахт!$D$5:$E$80)) * $S$1, "-")} -> 261000 | F13: {=IFERROR(_xlfn.XLOOKUP(1, (Фрахт!$A$5:$A$80 = $A13)* (Фрахт!$B$5:$B$80 = $C13) * (Фрахт!$C$5:$C$80 =$D13), _xlfn.XLOOKUP(1, (Фрахт!$D$4:$E$4 = F$2) * 1, Фрахт!$D$5:$E$80)) * $S$1, "-")} -> 372900 | G13: {=IFERROR(_xlfn.XLOOKUP(1, ('Drop off'!$A$6:$A$14 = $C13) * 1, _xlfn.XLOOKUP(1, ('Drop off'!$B$5:$I$5 = G$2) * ('Drop off'!$B$4:$I$4 = $S$2), 'Drop off'!$B$6:$I$14)) * $S$1, "-")} -> 0 | H13: {=IFERROR(_xlfn.XLOOKUP(1, ('Drop off'!$A$6:$A$14 = $C13) * 1, _xlfn.XLOOKUP(1, ('Drop off'!$B$5:$I$5 = H$2) * ('Drop off'!$B$4:$I$4 = $S$2), 'Drop off'!$B$6:$I$14)) * $S$1, "-")} -> 0 | I13: {=IFERROR(_xlfn.XLOOKUP(1, ('ж.д.'!$A$6:$A$14 = $D13) * 1, _xlfn.XLOOKUP(1, ('ж.д.'!$B$5:$M$5 = I$2) * ('ж.д.'!$B$4:$M$4 = $S$2), 'ж.д.'!$B$6:$M$14)), "-")} -> 134400 | J13: {=IFERROR(_xlfn.XLOOKUP(1, ('ж.д.'!$A$6:$A$14 = $D13) * 1, _xlfn.XLOOKUP(1, ('ж.д.'!$B$5:$M$5 = J$2) * ('ж.д.'!$B$4:$M$4 = $S$2), 'ж.д.'!$B$6:$M$14)), "-")} -> 149400 | K13: {=IFERROR(_xlfn.XLOOKUP(1, ('ж.д.'!$A$6:$A$14 = $D13) * 1, _xlfn.XLOOKUP(1, ('ж.д.'!$B$5:$M$5 = K$2) * ('ж.д.'!$B$4:$M$4 = $S$2), 'ж.д.'!$B$6:$M$14)), "-")} -> 235000 | L13: {=IF(ISNUMBER(SEARCH("Транс",$C13)),_xlfn.XLOOKUP(1,('Фрахт Транс'!$A$5:$A$10=$D13)*1,_xlfn.XLOOKUP(1,('Фрахт Транс'!$B$3:$M$3 = $S$2)*('Фрахт Транс'!$B$4:$M$4=L$2),'Фрахт Транс'!$B$5:$M$10)),SUM($E13, $G13, $I13, $O13))} -> 398794 | M13: {=IF(ISNUMBER(SEARCH("Транс",$C13)),_xlfn.XLOOKUP(1,('Фрахт Транс'!$A$5:$A$10=$D13)*1,_xlfn.XLOOKUP(1,('Фрахт Транс'!$B$3:$M$3=$S$2)*('Фрахт Транс'!$B$4:$M$4=M$2),'Фрахт Транс'!$B$5:$M$10)),SUM($E13, $G13, $J13, $O13))} -> 413794 | N13: {=IF(ISNUMBER(SEARCH("Транс",$C13)),_xlfn.XLOOKUP(1,('Фрахт Транс'!$A$5:$A$10=$D13)*1,_xlfn.XLOOKUP(1,('Фрахт Транс'!$B$3:$M$3=$S$2)*('Фрахт Транс'!$B$4:$M$4=N$2),'Фрахт Транс'!$B$5:$M$10)),SUM($F13, $H13, $K13, $P13))} -> 614701 | O13: {=IFERROR(_xlfn.XLOOKUP(1, (Охрана!$A$6:$A$14 = $D13) * 1, _xlfn.XLOOKUP(1, (Охрана!$B$5:$M$5 = O$2) * (Охрана!$B$4:$M$4 = $S$2), Охрана!$B$6:$M$14)), "-")} -> 3394 | P13: {=IFERROR(_xlfn.XLOOKUP(1, (Охрана!$A$6:$A$14 = $D13) * 1, _xlfn.XLOOKUP(1, (Охрана!$B$5:$M$5 = P$2) * (Охрана!$B$4:$M$4 = $S$2), Охрана!$B$6:$M$14)), "-")} -> 6801
A14: NINGBO | C14: EuroEast | D14: ВМПП/СОЛЛЕРС (Сквозной EuroEast) | E14: {=IFERROR(_xlfn.XLOOKUP(1, (Фрахт!$A$5:$A$80 = $A14)* (Фрахт!$B$5:$B$80 = $C14) * (Фрахт!$C$5:$C$80 =$D14), _xlfn.XLOOKUP(1, (Фрахт!$D$4:$E$4 = E$2) * 1, Фрахт!$D$5:$E$80)) * $S$1, "-")} -> - | F14: {=IFERROR(_xlfn.XLOOKUP(1, (Фрахт!$A$5:$A$80 = $A14)* (Фрахт!$B$5:$B$80 = $C14) * (Фрахт!$C$5:$C$80 =$D14), _xlfn.XLOOKUP(1, (Фрахт!$D$4:$E$4 = F$2) * 1, Фрахт!$D$5:$E$80)) * $S$1, "-")} -> - | G14: {=IFERROR(_xlfn.XLOOKUP(1, ('Drop off'!$A$6:$A$14 = $C14) * 1, _xlfn.XLOOKUP(1, ('Drop off'!$B$5:$I$5 = G$2) * ('Drop off'!$B$4:$I$4 = $S$2), 'Drop off'!$B$6:$I$14)) * $S$1, "-")} -> 0 | H14: {=IFERROR(_xlfn.XLOOKUP(1, ('Drop off'!$A$6:$A$14 = $C14) * 1, _xlfn.XLOOKUP(1, ('Drop off'!$B$5:$I$5 = H$2) * ('Drop off'!$B$4:$I$4 = $S$2), 'Drop off'!$B$6:$I$14)) * $S$1, "-")} -> 0 | I14: {=IFERROR(_xlfn.XLOOKUP(1, ('ж.д.'!$A$6:$A$14 = $D14) * 1, _xlfn.XLOOKUP(1, ('ж.д.'!$B$5:$M$5 = I$2) * ('ж.д.'!$B$4:$M$4 = $S$2), 'ж.д.'!$B$6:$M$14)), "-")} -> - | J14: {=IFERROR(_xlfn.XLOOKUP(1, ('ж.д.'!$A$6:$A$14 = $D14) * 1, _xlfn.XLOOKUP(1, ('ж.д.'!$B$5:$M$5 = J$2) * ('ж.д.'!$B$4:$M$4 = $S$2), 'ж.д.'!$B$6:$M$14)), "-")} -> - | K14: {=IFERROR(_xlfn.XLOOKUP(1, ('ж.д.'!$A$6:$A$14 = $D14) * 1, _xlfn.XLOOKUP(1, ('ж.д.'!$B$5:$M$5 = K$2) * ('ж.д.'!$B$4:$M$4 = $S$2), 'ж.д.'!$B$6:$M$14)), "-")} -> - | L14: {=IF(ISNUMBER(SEARCH("Транс",$C14)),_xlfn.XLOOKUP(1,('Фрахт Транс'!$A$5:$A$10=$D14)*1,_xlfn.XLOOKUP(1,('Фрахт Транс'!$B$3:$M$3 = $S$2)*('Фрахт Транс'!$B$4:$M$4=L$2),'Фрахт Транс'!$B$5:$M$10)),SUM($E14, $G14, $I14, $O14))} -> 0 | M14: {=IF(ISNUMBER(SEARCH("Транс",$C14)),_xlfn.XLOOKUP(1,('Фрахт Транс'!$A$5:$A$10=$D14)*1,_xlfn.XLOOKUP(1,('Фрахт Транс'!$B$3:$M$3=$S$2)*('Фрахт Транс'!$B$4:$M$4=M$2),'Фрахт Транс'!$B$5:$M$10)),SUM($E14, $G14, $J14, $O14))} -> 0 | N14: {=IF(ISNUMBER(SEARCH("Транс",$C14)),_xlfn.XLOOKUP(1,('Фрахт Транс'!$A$5:$A$10=$D14)*1,_xlfn.XLOOKUP(1,('Фрахт Транс'!$B$3:$M$3=$S$2)*('Фрахт Транс'!$B$4:$M$4=N$2),'Фрахт Транс'!$B$5:$M$10)),SUM($F14, $H14, $K14, $P14))} -> 0 | O14: {=IFERROR(_xlfn.XLOOKUP(1, (Охрана!$A$6:$A$14 = $D14) * 1, _xlfn.XLOOKUP(1, (Охрана!$B$5:$M$5 = O$2) * (Охрана!$B$4:$M$4 = $S$2), Охрана!$B$6:$M$14)), "-")} -> - | P14: {=IFERROR(_xlfn.XLOOKUP(1, (Охрана!$A$6:$A$14 = $D14) * 1, _xlfn.XLOOKUP(1, (Охрана!$B$5:$M$5 = P$2) * (Охрана!$B$4:$M$4 = $S$2), Охрана!$B$6:$M$14)), "-")} -> -
A15: NINGBO | C15: TFL (Сквозной) | D15: ВМТП (TFL) | E15: {=IFERROR(_xlfn.XLOOKUP(1, (Фрахт!$A$5:$A$80 = $A15)* (Фрахт!$B$5:$B$80 = $C15) * (Фрахт!$C$5:$C$80 =$D15), _xlfn.XLOOKUP(1, (Фрахт!$D$4:$E$4 = E$2) * 1, Фрахт!$D$5:$E$80)) * $S$1, "-")} -> - | F15: {=IFERROR(_xlfn.XLOOKUP(1, (Фрахт!$A$5:$A$80 = $A15)* (Фрахт!$B$5:$B$80 = $C15) * (Фрахт!$C$5:$C$80 =$D15), _xlfn.XLOOKUP(1, (Фрахт!$D$4:$E$4 = F$2) * 1, Фрахт!$D$5:$E$80)) * $S$1, "-")} -> - | G15: {=IFERROR(_xlfn.XLOOKUP(1, ('Drop off'!$A$6:$A$14 = $C15) * 1, _xlfn.XLOOKUP(1, ('Drop off'!$B$5:$I$5 = G$2) * ('Drop off'!$B$4:$I$4 = $S$2), 'Drop off'!$B$6:$I$14)) * $S$1, "-")} -> - | H15: {=IFERROR(_xlfn.XLOOKUP(1, ('Drop off'!$A$6:$A$14 = $C15) * 1, _xlfn.XLOOKUP(1, ('Drop off'!$B$5:$I$5 = H$2) * ('Drop off'!$B$4:$I$4 = $S$2), 'Drop off'!$B$6:$I$14)) * $S$1, "-")} -> - | I15: {=IFERROR(_xlfn.XLOOKUP(1, ('ж.д.'!$A$6:$A$14 = $D15) * 1, _xlfn.XLOOKUP(1, ('ж.д.'!$B$5:$M$5 = I$2) * ('ж.д.'!$B$4:$M$4 = $S$2), 'ж.д.'!$B$6:$M$14)), "-")} -> - | J15: {=IFERROR(_xlfn.XLOOKUP(1, ('ж.д.'!$A$6:$A$14 = $D15) * 1, _xlfn.XLOOKUP(1, ('ж.д.'!$B$5:$M$5 = J$2) * ('ж.д.'!$B$4:$M$4 = $S$2), 'ж.д.'!$B$6:$M$14)), "-")} -> - | K15: {=IFERROR(_xlfn.XLOOKUP(1, ('ж.д.'!$A$6:$A$14 = $D15) * 1, _xlfn.XLOOKUP(1, ('ж.д.'!$B$5:$M$5 = K$2) * ('ж.д.'!$B$4:$M$4 = $S$2), 'ж.д.'!$B$6:$M$14)), "-")} -> - | L15: {=IF(ISNUMBER(SEARCH("Транс",$C15)),_xlfn.XLOOKUP(1,('Фрахт Транс'!$A$5:$A$10=$D15)*1,_xlfn.XLOOKUP(1,('Фрахт Транс'!$B$3:$M$3 = $S$2)*('Фрахт Транс'!$B$4:$M$4=L$2),'Фрахт Транс'!$B$5:$M$10)),SUM($E15, $G15, $I15, $O15))} -> 0 | M15: {=IF(ISNUMBER(SEARCH("Транс",$C15)),_xlfn.XLOOKUP(1,('Фрахт Транс'!$A$5:$A$10=$D15)*1,_xlfn.XLOOKUP(1,('Фрахт Транс'!$B$3:$M$3=$S$2)*('Фрахт Транс'!$B$4:$M$4=M$2),'Фрахт Транс'!$B$5:$M$10)),SUM($E15, $G15, $J15, $O15))} -> 0 | N15: {=IF(ISNUMBER(SEARCH("Транс",$C15)),_xlfn.XLOOKUP(1,('Фрахт Транс'!$A$5:$A$10=$D15)*1,_xlfn.XLOOKUP(1,('Фрахт Транс'!$B$3:$M$3=$S$2)*('Фрахт Транс'!$B$4:$M$4=N$2),'Фрахт Транс'!$B$5:$M$10)),SUM($F15, $H15, $K15, $P15))} -> 0 | O15: {=IFERROR(_xlfn.XLOOKUP(1, (Охрана!$A$6:$A$14 = $D15) * 1, _xlfn.XLOOKUP(1, (Охрана!$B$5:$M$5 = O$2) * (Охрана!$B$4:$M$4 = $S$2), Охрана!$B$6:$M$14)), "-")} -> - | P15: {=IFERROR(_xlfn.XLOOKUP(1, (Охрана!$A$6:$A$14 = $D15) * 1, _xlfn.XLOOKUP(1, (Охрана!$B$5:$M$5 = P$2) * (Охрана!$B$4:$M$4 = $S$2), Охрана!$B$6:$M$14)), "-")} -> -
... A17: NINGBO | C17: SASCO | D17: ВМКТ | E17: {=IFERROR(_xlfn.XLOOKUP(1, (Фрахт!$A$5:$A$80 = $A17)* (Фрахт!$B$5:$B$80 = $C17) * (Фрахт!$C$5:$C$80 =$D17), _xlfn.XLOOKUP(1, (Фрахт!$D$4:$E$4 = E$2) * 1, Фрахт!$D$5:$E$80)) * $S$1, "-")} -> 315000 | F17: {=IFERROR(_xlfn.XLOOKUP(1, (Фрахт!$A$5:$A$80 = $A17)* (Фрахт!$B$5:$B$80 = $C17) * (Фрахт!$C$5:$C$80 =$D17), _xlfn.XLOOKUP(1, (Фрахт!$D$4:$E$4 = F$2) * 1, Фрахт!$D$5:$E$80)) * $S$1, "-")} -> 420000 | G17: {=IFERROR(_xlfn.XLOOKUP(1, ('Drop off'!$A$6:$A$14 = $C17) * 1, _xlfn.XLOOKUP(1, ('Drop off'!$B$5:$I$5 = G$2) * ('Drop off'!$B$4:$I$4 = $S$2), 'Drop off'!$B$6:$I$14)) * $S$1, "-")} -> 0 | H17: {=IFERROR(_xlfn.XLOOKUP(1, ('Drop off'!$A$6:$A$14 = $C17) * 1, _xlfn.XLOOKUP(1, ('Drop off'!$B$5:$I$5 = H$2) * ('Drop off'!$B$4:$I$4 = $S$2), 'Drop off'!$B$6:$I$14)) * $S$1, "-")} -> 0 | I17: {=IFERROR(_xlfn.XLOOKUP(1, ('ж.д.'!$A$6:$A$14 = $D17) * 1, _xlfn.XLOOKUP(1, ('ж.д.'!$B$5:$M$5 = I$2) * ('ж.д.'!$B$4:$M$4 = $S$2), 'ж.д.'!$B$6:$M$14)), "-")} -> 125000 | J17: {=IFERROR(_xlfn.XLOOKUP(1, ('ж.д.'!$A$6:$A$14 = $D17) * 1, _xlfn.XLOOKUP(1, ('ж.д.'!$B$5:$M$5 = J$2) * ('ж.д.'!$B$4:$M$4 = $S$2), 'ж.д.'!$B$6:$M$14)), "-")} -> 140000 | K17: {=IFERROR(_xlfn.XLOOKUP(1, ('ж.д.'!$A$6:$A$14 = $D17) * 1, _xlfn.XLOOKUP(1, ('ж.д.'!$B$5:$M$5 = K$2) * ('ж.д.'!$B$4:$M$4 = $S$2), 'ж.д.'!$B$6:$M$14)), "-")} -> 227000 | L17: {=IF(ISNUMBER(SEARCH("Транс",$C17)),_xlfn.XLOOKUP(1,('Фрахт Транс'!$A$5:$A$10=$D17)*1,_xlfn.XLOOKUP(1,('Фрахт Транс'!$B$3:$M$3 = $S$2)*('Фрахт Транс'!$B$4:$M$4=L$2),'Фрахт Транс'!$B$5:$M$10)),SUM($E17, $G17, $I17, $O17))} -> 444100 | M17: {=IF(ISNUMBER(SEARCH("Транс",$C17)),_xlfn.XLOOKUP(1,('Фрахт Транс'!$A$5:$A$10=$D17)*1,_xlfn.XLOOKUP(1,('Фрахт Транс'!$B$3:$M$3=$S$2)*('Фрахт Транс'!$B$4:$M$4=M$2),'Фрахт Транс'!$B$5:$M$10)),SUM($E17, $G17, $J17, $O17))} -> 459100 | N17: {=IF(ISNUMBER(SEARCH("Транс",$C17)),_xlfn.XLOOKUP(1,('Фрахт Транс'!$A$5:$A$10=$D17)*1,_xlfn.XLOOKUP(1,('Фрахт Транс'!$B$3:$M$3=$S$2)*('Фрахт Транс'!$B$4:$M$4=N$2),'Фрахт Транс'!$B$5:$M$10)),SUM($F17, $H17, $K17, $P17))} -> 655200 | O17: {=IFERROR(_xlfn.XLOOKUP(1, (Охрана!$A$6:$A$14 = $D17) * 1, _xlfn.XLOOKUP(1, (Охрана!$B$5:$M$5 = O$2) * (Охрана!$B$4:$M$4 = $S$2), Охрана!$B$6:$M$14)), "-")} -> 4100 | P17: {=IFERROR(_xlfn.XLOOKUP(1, (Охрана!$A$6:$A$14 = $D17) * 1, _xlfn.XLOOKUP(1, (Охрана!$B$5:$M$5 = P$2) * (Охрана!$B$4:$M$4 = $S$2), Охрана!$B$6:$M$14)), "-")} -> 8200
A18: SHANGHAI | B18: SHANGHAI | C18: Трансконтейнер (Сквозной сервис) | D18: ВСК (ТК) Shanghai | E18: {=IFERROR(_xlfn.XLOOKUP(1, (Фрахт!$A$5:$A$80 = $A18)* (Фрахт!$B$5:$B$80 = $C18) * (Фрахт!$C$5:$C$80 =$D18), _xlfn.XLOOKUP(1, (Фрахт!$D$4:$E$4 = E$2) * 1, Фрахт!$D$5:$E$80)) * $S$1, "-")} -> - | F18: {=IFERROR(_xlfn.XLOOKUP(1, (Фрахт!$A$5:$A$80 = $A18)* (Фрахт!$B$5:$B$80 = $C18) * (Фрахт!$C$5:$C$80 =$D18), _xlfn.XLOOKUP(1, (Фрахт!$D$4:$E$4 = F$2) * 1, Фрахт!$D$5:$E$80)) * $S$1, "-")} -> - | G18: {=IFERROR(_xlfn.XLOOKUP(1, ('Drop off'!$A$6:$A$14 = $C18) * 1, _xlfn.XLOOKUP(1, ('Drop off'!$B$5:$I$5 = G$2) * ('Drop off'!$B$4:$I$4 = $S$2), 'Drop off'!$B$6:$I$14)) * $S$1, "-")} -> 0 | H18: {=IFERROR(_xlfn.XLOOKUP(1, ('Drop off'!$A$6:$A$14 = $C18) * 1, _xlfn.XLOOKUP(1, ('Drop off'!$B$5:$I$5 = H$2) * ('Drop off'!$B$4:$I$4 = $S$2), 'Drop off'!$B$6:$I$14)) * $S$1, "-")} -> 0 | I18: {=IFERROR(_xlfn.XLOOKUP(1, ('ж.д.'!$A$6:$A$14 = $D18) * 1, _xlfn.XLOOKUP(1, ('ж.д.'!$B$5:$M$5 = I$2) * ('ж.д.'!$B$4:$M$4 = $S$2), 'ж.д.'!$B$6:$M$14)), "-")} -> - | J18: {=IFERROR(_xlfn.XLOOKUP(1, ('ж.д.'!$A$6:$A$14 = $D18) * 1, _xlfn.XLOOKUP(1, ('ж.д.'!$B$5:$M$5 = J$2) * ('ж.д.'!$B$4:$M$4 = $S$2), 'ж.д.'!$B$6:$M$14)), "-")} -> - | K18: {=IFERROR(_xlfn.XLOOKUP(1, ('ж.д.'!$A$6:$A$14 = $D18) * 1, _xlfn.XLOOKUP(1, ('ж.д.'!$B$5:$M$5 = K$2) * ('ж.д.'!$B$4:$M$4 = $S$2), 'ж.д.'!$B$6:$M$14)), "-")} -> - | L18: {=IF(ISNUMBER(SEARCH("Транс",$C18)),_xlfn.XLOOKUP(1,('Фрахт Транс'!$A$5:$A$10=$D18)*1,_xlfn.XLOOKUP(1,('Фрахт Транс'!$B$3:$M$3 = $S$2)*('Фрахт Транс'!$B$4:$M$4=L$2),'Фрахт Транс'!$B$5:$M$10)),SUM($E18, $G18, $I18, $O18))} -> 356456 | M18: {=IF(ISNUMBER(SEARCH("Транс",$C18)),_xlfn.XLOOKUP(1,('Фрахт Транс'!$A$5:$A$10=$D18)*1,_xlfn.XLOOKUP(1,('Фрахт Транс'!$B$3:$M$3=$S$2)*('Фрахт Транс'!$B$4:$M$4=M$2),'Фрахт Транс'!$B$5:$M$10)),SUM($E18, $G18, $J18, $O18))} -> 373994 | N18: {=IF(ISNUMBER(SEARCH("Транс",$C18)),_xlfn.XLOOKUP(1,('Фрахт Транс'!$A$5:$A$10=$D18)*1,_xlfn.XLOOKUP(1,('Фрахт Транс'!$B$3:$M$3=$S$2)*('Фрахт Транс'!$B$4:$M$4=N$2),'Фрахт Транс'!$B$5:$M$10)),SUM($F18, $H18, $K18, $P18))} -> 519968 | O18: {=IFERROR(_xlfn.XLOOKUP(1, (Охрана!$A$6:$A$14 = $D18) * 1, _xlfn.XLOOKUP(1, (Охрана!$B$5:$M$5 = O$2) * (Охрана!$B$4:$M$4 = $S$2), Охрана!$B$6:$M$14)), "-")} -> - | P18: {=IFERROR(_xlfn.XLOOKUP(1, (Охрана!$A$6:$A$14 = $D18) * 1, _xlfn.XLOOKUP(1, (Охрана!$B$5:$M$5 = P$2) * (Охрана!$B$4:$M$4 = $S$2), Охрана!$B$6:$M$14)), "-")} -> -
A19: SHANGHAI | C19: ФЕСКО | D19: ВМТП (Феско) | E19: {=IFERROR(_xlfn.XLOOKUP(1, (Фрахт!$A$5:$A$80 = $A19)* (Фрахт!$B$5:$B$80 = $C19) * (Фрахт!$C$5:$C$80 =$D19), _xlfn.XLOOKUP(1, (Фрахт!$D$4:$E$4 = E$2) * 1, Фрахт!$D$5:$E$80)) * $S$1, "-")} -> 330000 | F19: {=IFERROR(_xlfn.XLOOKUP(1, (Фрахт!$A$5:$A$80 = $A19)* (Фрахт!$B$5:$B$80 = $C19) * (Фрахт!$C$5:$C$80 =$D19), _xlfn.XLOOKUP(1, (Фрахт!$D$4:$E$4 = F$2) * 1, Фрахт!$D$5:$E$80)) * $S$1, "-")} -> 450000 | G19: {=IFERROR(_xlfn.XLOOKUP(1, ('Drop off'!$A$6:$A$14 = $C19) * 1, _xlfn.XLOOKUP(1, ('Drop off'!$B$5:$I$5 = G$2) * ('Drop off'!$B$4:$I$4 = $S$2), 'Drop off'!$B$6:$I$14)) * $S$1, "-")} -> 0 | H19: {=IFERROR(_xlfn.XLOOKUP(1, ('Drop off'!$A$6:$A$14 = $C19) * 1, _xlfn.XLOOKUP(1, ('Drop off'!$B$5:$I$5 = H$2) * ('Drop off'!$B$4:$I$4 = $S$2), 'Drop off'!$B$6:$I$14)) * $S$1, "-")} -> 0 | I19: {=IFERROR(_xlfn.XLOOKUP(1, ('ж.д.'!$A$6:$A$14 = $D19) * 1, _xlfn.XLOOKUP(1, ('ж.д.'!$B$5:$M$5 = I$2) * ('ж.д.'!$B$4:$M$4 = $S$2), 'ж.д.'!$B$6:$M$14)), "-")} -> 167600 | J19: {=IFERROR(_xlfn.XLOOKUP(1, ('ж.д.'!$A$6:$A$14 = $D19) * 1, _xlfn.XLOOKUP(1, ('ж.д.'!$B$5:$M$5 = J$2) * ('ж.д.'!$B$4:$M$4 = $S$2), 'ж.д.'!$B$6:$M$14)), "-")} -> 181540 | K19: {=IFERROR(_xlfn.XLOOKUP(1, ('ж.д.'!$A$6:$A$14 = $D19) * 1, _xlfn.XLOOKUP(1, ('ж.д.'!$B$5:$M$5 = K$2) * ('ж.д.'!$B$4:$M$4 = $S$2), 'ж.д.'!$B$6:$M$14)), "-")} -> 292000 | L19: {=IF(ISNUMBER(SEARCH("Транс",$C19)),_xlfn.XLOOKUP(1,('Фрахт Транс'!$A$5:$A$10=$D19)*1,_xlfn.XLOOKUP(1,('Фрахт Транс'!$B$3:$M$3 = $S$2)*('Фрахт Транс'!$B$4:$M$4=L$2),'Фрахт Транс'!$B$5:$M$10)),SUM($E19, $G19, $I19, $O19))} -> 501422 | M19: {=IF(ISNUMBER(SEARCH("Транс",$C19)),_xlfn.XLOOKUP(1,('Фрахт Транс'!$A$5:$A$10=$D19)*1,_xlfn.XLOOKUP(1,('Фрахт Транс'!$B$3:$M$3=$S$2)*('Фрахт Транс'!$B$4:$M$4=M$2),'Фрахт Транс'!$B$5:$M$10)),SUM($E19, $G19, $J19, $O19))} -> 515362 | N19: {=IF(ISNUMBER(SEARCH("Транс",$C19)),_xlfn.XLOOKUP(1,('Фрахт Транс'!$A$5:$A$10=$D19)*1,_xlfn.XLOOKUP(1,('Фрахт Транс'!$B$3:$M$3=$S$2)*('Фрахт Транс'!$B$4:$M$4=N$2),'Фрахт Транс'!$B$5:$M$10)),SUM($F19, $H19, $K19, $P19))} -> 748910 | O19: {=IFERROR(_xlfn.XLOOKUP(1, (Охрана!$A$6:$A$14 = $D19) * 1, _xlfn.XLOOKUP(1, (Охрана!$B$5:$M$5 = O$2) * (Охрана!$B$4:$M$4 = $S$2), Охрана!$B$6:$M$14)), "-")} -> 3822 | P19: {=IFERROR(_xlfn.XLOOKUP(1, (Охрана!$A$6:$A$14 = $D19) * 1, _xlfn.XLOOKUP(1, (Охрана!$B$5:$M$5 = P$2) * (Охрана!$B$4:$M$4 = $S$2), Охрана!$B$6:$M$14)), "-")} -> 6910
A20: SHANGHAI | C20: ФЕСКО | D20: ВМТП (Феско ост.) | E20: {=IFERROR(_xlfn.XLOOKUP(1, (Фрахт!$A$5:$A$80 = $A20)* (Фрахт!$B$5:$B$80 = $C20) * (Фрахт!$C$5:$C$80 =$D20), _xlfn.XLOOKUP(1, (Фрахт!$D$4:$E$4 = E$2) * 1, Фрахт!$D$5:$E$80)) * $S$1, "-")} -> 330000 | F20: {=IFERROR(_xlfn.XLOOKUP(1, (Фрахт!$A$5:$A$80 = $A20)* (Фрахт!$B$5:$B$80 = $C20) * (Фрахт!$C$5:$C$80 =$D20), _xlfn.XLOOKUP(1, (Фрахт!$D$4:$E$4 = F$2) * 1, Фрахт!$D$5:$E$80)) * $S$1, "-")} -> 450000 | G20: {=IFERROR(_xlfn.XLOOKUP(1, ('Drop off'!$A$6:$A$14 = $C20) * 1, _xlfn.XLOOKUP(1, ('Drop off'!$B$5:$I$5 = G$2) * ('Drop off'!$B$4:$I$4 = $S$2), 'Drop off'!$B$6:$I$14)) * $S$1, "-")} -> 0 | H20: {=IFERROR(_xlfn.XLOOKUP(1, ('Drop off'!$A$6:$A$14 = $C20) * 1, _xlfn.XLOOKUP(1, ('Drop off'!$B$5:$I$5 = H$2) * ('Drop off'!$B$4:$I$4 = $S$2), 'Drop off'!$B$6:$I$14)) * $S$1, "-")} -> 0 | I20: {=IFERROR(_xlfn.XLOOKUP(1, ('ж.д.'!$A$6:$A$14 = $D20) * 1, _xlfn.XLOOKUP(1, ('ж.д.'!$B$5:$M$5 = I$2) * ('ж.д.'!$B$4:$M$4 = $S$2), 'ж.д.'!$B$6:$M$14)), "-")} -> 173730 | J20: {=IFERROR(_xlfn.XLOOKUP(1, ('ж.д.'!$A$6:$A$14 = $D20) * 1, _xlfn.XLOOKUP(1, ('ж.д.'!$B$5:$M$5 = J$2) * ('ж.д.'!$B$4:$M$4 = $S$2), 'ж.д.'!$B$6:$M$14)), "-")} -> 191045 | K20: {=IFERROR(_xlfn.XLOOKUP(1, ('ж.д.'!$A$6:$A$14 = $D20) * 1, _xlfn.XLOOKUP(1, ('ж.д.'!$B$5:$M$5 = K$2) * ('ж.д.'!$B$4:$M$4 = $S$2), 'ж.д.'!$B$6:$M$14)), "-")} -> 303815 | L20: {=IF(ISNUMBER(SEARCH("Транс",$C20)),_xlfn.XLOOKUP(1,('Фрахт Транс'!$A$5:$A$10=$D20)*1,_xlfn.XLOOKUP(1,('Фрахт Транс'!$B$3:$M$3 = $S$2)*('Фрахт Транс'!$B$4:$M$4=L$2),'Фрахт Транс'!$B$5:$M$10)),SUM($E20, $G20, $I20, $O20))} -> 507552 | M20: {=IF(ISNUMBER(SEARCH("Транс",$C20)),_xlfn.XLOOKUP(1,('Фрахт Транс'!$A$5:$A$10=$D20)*1,_xlfn.XLOOKUP(1,('Фрахт Транс'!$B$3:$M$3=$S$2)*('Фрахт Транс'!$B$4:$M$4=M$2),'Фрахт Транс'!$B$5:$M$10)),SUM($E20, $G20, $J20, $O20))} -> 524867 | N20: {=IF(ISNUMBER(SEARCH("Транс",$C20)),_xlfn.XLOOKUP(1,('Фрахт Транс'!$A$5:$A$10=$D20)*1,_xlfn.XLOOKUP(1,('Фрахт Транс'!$B$3:$M$3=$S$2)*('Фрахт Транс'!$B$4:$M$4=N$2),'Фрахт Транс'!$B$5:$M$10)),SUM($F20, $H20, $K20, $P20))} -> 760725 | O20: {=IFERROR(_xlfn.XLOOKUP(1, (Охрана!$A$6:$A$14 = $D20) * 1, _xlfn.XLOOKUP(1, (Охрана!$B$5:$M$5 = O$2) * (Охрана!$B$4:$M$4 = $S$2), Охрана!$B$6:$M$14)), "-")} -> 3822 | P20: {=IFERROR(_xlfn.XLOOKUP(1, (Охрана!$A$6:$A$14 = $D20) * 1, _xlfn.XLOOKUP(1, (Охрана!$B$5:$M$5 = P$2) * (Охрана!$B$4:$M$4 = $S$2), Охрана!$B$6:$M$14)), "-")} -> 6910
A21: SHANGHAI | C21: SINOKOR | D21: ВСК | E21: {=IFERROR(_xlfn.XLOOKUP(1, (Фрахт!$A$5:$A$80 = $A21)* (Фрахт!$B$5:$B$80 = $C21) * (Фрахт!$C$5:$C$80 =$D21), _xlfn.XLOOKUP(1, (Фрахт!$D$4:$E$4 = E$2) * 1, Фрахт!$D$5:$E$80)) * $S$1, "-")} -> 283500 | F21: {=IFERROR(_xlfn.XLOOKUP(1, (Фрахт!$A$5:$A$80 = $A21)* (Фрахт!$B$5:$B$80 = $C21) * (Фрахт!$C$5:$C$80 =$D21), _xlfn.XLOOKUP(1, (Фрахт!$D$4:$E$4 = F$2) * 1, Фрахт!$D$5:$E$80)) * $S$1, "-")} -> 472500 | G21: {=IFERROR(_xlfn.XLOOKUP(1, ('Drop off'!$A$6:$A$14 = $C21) * 1, _xlfn.XLOOKUP(1, ('Drop off'!$B$5:$I$5 = G$2) * ('Drop off'!$B$4:$I$4 = $S$2), 'Drop off'!$B$6:$I$14)) * $S$1, "-")} -> 56700 | H21: {=IFERROR(_xlfn.XLOOKUP(1, ('Drop off'!$A$6:$A$14 = $C21) * 1, _xlfn.XLOOKUP(1, ('Drop off'!$B$5:$I$5 = H$2) * ('Drop off'!$B$4:$I$4 = $S$2), 'Drop off'!$B$6:$I$14)) * $S$1, "-")} -> 37800 | I21: {=IFERROR(_xlfn.XLOOKUP(1, ('ж.д.'!$A$6:$A$14 = $D21) * 1, _xlfn.XLOOKUP(1, ('ж.д.'!$B$5:$M$5 = I$2) * ('ж.д.'!$B$4:$M$4 = $S$2), 'ж.д.'!$B$6:$M$14)), "-")} -> 122400 | J21: {=IFERROR(_xlfn.XLOOKUP(1, ('ж.д.'!$A$6:$A$14 = $D21) * 1, _xlfn.XLOOKUP(1, ('ж.д.'!$B$5:$M$5 = J$2) * ('ж.д.'!$B$4:$M$4 = $S$2), 'ж.д.'!$B$6:$M$14)), "-")} -> 139800 | K21: {=IFERROR(_xlfn.XLOOKUP(1, ('ж.д.'!$A$6:$A$14 = $D21) * 1, _xlfn.XLOOKUP(1, ('ж.д.'!$B$5:$M$5 = K$2) * ('ж.д.'!$B$4:$M$4 = $S$2), 'ж.д.'!$B$6:$M$14)), "-")} -> 224600 | L21: {=IF(ISNUMBER(SEARCH("Транс",$C21)),_xlfn.XLOOKUP(1,('Фрахт Транс'!$A$5:$A$10=$D21)*1,_xlfn.XLOOKUP(1,('Фрахт Транс'!$B$3:$M$3 = $S$2)*('Фрахт Транс'!$B$4:$M$4=L$2),'Фрахт Транс'!$B$5:$M$10)),SUM($E21, $G21, $I21, $O21))} -> 465994 | M21: {=IF(ISNUMBER(SEARCH("Транс",$C21)),_xlfn.XLOOKUP(1,('Фрахт Транс'!$A$5:$A$10=$D21)*1,_xlfn.XLOOKUP(1,('Фрахт Транс'!$B$3:$M$3=$S$2)*('Фрахт Транс'!$B$4:$M$4=M$2),'Фрахт Транс'!$B$5:$M$10)),SUM($E21, $G21, $J21, $O21))} -> 483394 | N21: {=IF(ISNUMBER(SEARCH("Транс",$C21)),_xlfn.XLOOKUP(1,('Фрахт Транс'!$A$5:$A$10=$D21)*1,_xlfn.XLOOKUP(1,('Фрахт Транс'!$B$3:$M$3=$S$2)*('Фрахт Транс'!$B$4:$M$4=N$2),'Фрахт Транс'!$B$5:$M$10)),SUM($F21, $H21, $K21, $P21))} -> 741701 | O21: {=IFERROR(_xlfn.XLOOKUP(1, (Охрана!$A$6:$A$14 = $D21) * 1, _xlfn.XLOOKUP(1, (Охрана!$B$5:$M$5 = O$2) * (Охрана!$B$4:$M$4 = $S$2), Охрана!$B$6:$M$14)), "-")} -> 3394 | P21: {=IFERROR(_xlfn.XLOOKUP(1, (Охрана!$A$6:$A$14 = $D21) * 1, _xlfn.XLOOKUP(1, (Охрана!$B$5:$M$5 = P$2) * (Охрана!$B$4:$M$4 = $S$2), Охрана!$B$6:$M$14)), "-")} -> 6801
A22: SHANGHAI | C22: SINOKOR | D22: Соллерс | E22: {=IFERROR(_xlfn.XLOOKUP(1, (Фрахт!$A$5:$A$80 = $A22)* (Фрахт!$B$5:$B$80 = $C22) * (Фрахт!$C$5:$C$80 =$D22), _xlfn.XLOOKUP(1, (Фрахт!$D$4:$E$4 = E$2) * 1, Фрахт!$D$5:$E$80)) * $S$1, "-")} -> 283500 | F22: {=IFERROR(_xlfn.XLOOKUP(1, (Фрахт!$A$5:$A$80 = $A22)* (Фрахт!$B$5:$B$80 = $C22) * (Фрахт!$C$5:$C$80 =$D22), _xlfn.XLOOKUP(1, (Фрахт!$D$4:$E$4 = F$2) * 1, Фрахт!$D$5:$E$80)) * $S$1, "-")} -> 472500 | G22: {=IFERROR(_xlfn.XLOOKUP(1, ('Drop off'!$A$6:$A$14 = $C22) * 1, _xlfn.XLOOKUP(1, ('Drop off'!$B$5:$I$5 = G$2) * ('Drop off'!$B$4:$I$4 = $S$2), 'Drop off'!$B$6:$I$14)) * $S$1, "-")} -> 56700 | H22: {=IFERROR(_xlfn.XLOOKUP(1, ('Drop off'!$A$6:$A$14 = $C22) * 1, _xlfn.XLOOKUP(1, ('Drop off'!$B$5:$I$5 = H$2) * ('Drop off'!$B$4:$I$4 = $S$2), 'Drop off'!$B$6:$I$14)) * $S$1, "-")} -> 37800 | I22: {=IFERROR(_xlfn.XLOOKUP(1, ('ж.д.'!$A$6:$A$14 = $D22) * 1, _xlfn.XLOOKUP(1, ('ж.д.'!$B$5:$M$5 = I$2) * ('ж.д.'!$B$4:$M$4 = $S$2), 'ж.д.'!$B$6:$M$14)), "-")} -> 134400 | J22: {=IFERROR(_xlfn.XLOOKUP(1, ('ж.д.'!$A$6:$A$14 = $D22) * 1, _xlfn.XLOOKUP(1, ('ж.д.'!$B$5:$M$5 = J$2) * ('ж.д.'!$B$4:$M$4 = $S$2), 'ж.д.'!$B$6:$M$14)), "-")} -> 149400 | K22: {=IFERROR(_xlfn.XLOOKUP(1, ('ж.д.'!$A$6:$A$14 = $D22) * 1, _xlfn.XLOOKUP(1, ('ж.д.'!$B$5:$M$5 = K$2) * ('ж.д.'!$B$4:$M$4 = $S$2), 'ж.д.'!$B$6:$M$14)), "-")} -> 235000 | L22: {=IF(ISNUMBER(SEARCH("Транс",$C22)),_xlfn.XLOOKUP(1,('Фрахт Транс'!$A$5:$A$10=$D22)*1,_xlfn.XLOOKUP(1,('Фрахт Транс'!$B$3:$M$3 = $S$2)*('Фрахт Транс'!$B$4:$M$4=L$2),'Фрахт Транс'!$B$5:$M$10)),SUM($E22, $G22, $I22, $O22))} -> 477994 | M22: {=IF(ISNUMBER(SEARCH("Транс",$C22)),_xlfn.XLOOKUP(1,('Фрахт Транс'!$A$5:$A$10=$D22)*1,_xlfn.XLOOKUP(1,('Фрахт Транс'!$B$3:$M$3=$S$2)*('Фрахт Транс'!$B$4:$M$4=M$2),'Фрахт Транс'!$B$5:$M$10)),SUM($E22, $G22, $J22, $O22))} -> 492994 | N22: {=IF(ISNUMBER(SEARCH("Транс",$C22)),_xlfn.XLOOKUP(1,('Фрахт Транс'!$A$5:$A$10=$D22)*1,_xlfn.XLOOKUP(1,('Фрахт Транс'!$B$3:$M$3=$S$2)*('Фрахт Транс'!$B$4:$M$4=N$2),'Фрахт Транс'!$B$5:$M$10)),SUM($F22, $H22, $K22, $P22))} -> 752101 | O22: {=IFERROR(_xlfn.XLOOKUP(1, (Охрана!$A$6:$A$14 = $D22) * 1, _xlfn.XLOOKUP(1, (Охрана!$B$5:$M$5 = O$2) * (Охрана!$B$4:$M$4 = $S$2), Охрана!$B$6:$M$14)), "-")} -> 3394 | P22: {=IFERROR(_xlfn.XLOOKUP(1, (Охрана!$A$6:$A$14 = $D22) * 1, _xlfn.XLOOKUP(1, (Охрана!$B$5:$M$5 = P$2) * (Охрана!$B$4:$M$4 = $S$2), Охрана!$B$6:$M$14)), "-")} -> 6801
A23: SHANGHAI | C23: SINOKOR | D23: ВМТП | E23: {=IFERROR(_xlfn.XLOOKUP(1, (Фрахт!$A$5:$A$80 = $A23)* (Фрахт!$B$5:$B$80 = $C23) * (Фрахт!$C$5:$C$80 =$D23), _xlfn.XLOOKUP(1, (Фрахт!$D$4:$E$4 = E$2) * 1, Фрахт!$D$5:$E$80)) * $S$1, "-")} -> 283500 | F23: {=IFERROR(_xlfn.XLOOKUP(1, (Фрахт!$A$5:$A$80 = $A23)* (Фрахт!$B$5:$B$80 = $C23) * (Фрахт!$C$5:$C$80 =$D23), _xlfn.XLOOKUP(1, (Фрахт!$D$4:$E$4 = F$2) * 1, Фрахт!$D$5:$E$80)) * $S$1, "-")} -> 472500 | G23: {=IFERROR(_xlfn.XLOOKUP(1, ('Drop off'!$A$6:$A$14 = $C23) * 1, _xlfn.XLOOKUP(1, ('Drop off'!$B$5:$I$5 = G$2) * ('Drop off'!$B$4:$I$4 = $S$2), 'Drop off'!$B$6:$I$14)) * $S$1, "-")} -> 56700 | H23: {=IFERROR(_xlfn.XLOOKUP(1, ('Drop off'!$A$6:$A$14 = $C23) * 1, _xlfn.XLOOKUP(1, ('Drop off'!$B$5:$I$5 = H$2) * ('Drop off'!$B$4:$I$4 = $S$2), 'Drop off'!$B$6:$I$14)) * $S$1, "-")} -> 37800 | I23: {=IFERROR(_xlfn.XLOOKUP(1, ('ж.д.'!$A$6:$A$14 = $D23) * 1, _xlfn.XLOOKUP(1, ('ж.д.'!$B$5:$M$5 = I$2) * ('ж.д.'!$B$4:$M$4 = $S$2), 'ж.д.'!$B$6:$M$14)), "-")} -> 141000 | J23: {=IFERROR(_xlfn.XLOOKUP(1, ('ж.д.'!$A$6:$A$14 = $D23) * 1, _xlfn.XLOOKUP(1, ('ж.д.'!$B$5:$M$5 = J$2) * ('ж.д.'!$B$4:$M$4 = $S$2), 'ж.д.'!$B$6:$M$14)), "-")} -> 156600 | K23: {=IFERROR(_xlfn.XLOOKUP(1, ('ж.д.'!$A$6:$A$14 = $D23) * 1, _xlfn.XLOOKUP(1, ('ж.д.'!$B$5:$M$5 = K$2) * ('ж.д.'!$B$4:$M$4 = $S$2), 'ж.д.'!$B$6:$M$14)), "-")} -> 261000 | L23: {=IF(ISNUMBER(SEARCH("Транс",$C23)),_xlfn.XLOOKUP(1,('Фрахт Транс'!$A$5:$A$10=$D23)*1,_xlfn.XLOOKUP(1,('Фрахт Транс'!$B$3:$M$3 = $S$2)*('Фрахт Транс'!$B$4:$M$4=L$2),'Фрахт Транс'!$B$5:$M$10)),SUM($E23, $G23, $I23, $O23))} -> 485022 | M23: {=IF(ISNUMBER(SEARCH("Транс",$C23)),_xlfn.XLOOKUP(1,('Фрахт Транс'!$A$5:$A$10=$D23)*1,_xlfn.XLOOKUP(1,('Фрахт Транс'!$B$3:$M$3=$S$2)*('Фрахт Транс'!$B$4:$M$4=M$2),'Фрахт Транс'!$B$5:$M$10)),SUM($E23, $G23, $J23, $O23))} -> 500622 | N23: {=IF(ISNUMBER(SEARCH("Транс",$C23)),_xlfn.XLOOKUP(1,('Фрахт Транс'!$A$5:$A$10=$D23)*1,_xlfn.XLOOKUP(1,('Фрахт Транс'!$B$3:$M$3=$S$2)*('Фрахт Транс'!$B$4:$M$4=N$2),'Фрахт Транс'!$B$5:$M$10)),SUM($F23, $H23, $K23, $P23))} -> 778210 | O23: {=IFERROR(_xlfn.XLOOKUP(1, (Охрана!$A$6:$A$14 = $D23) * 1, _xlfn.XLOOKUP(1, (Охрана!$B$5:$M$5 = O$2) * (Охрана!$B$4:$M$4 = $S$2), Охрана!$B$6:$M$14)), "-")} -> 3822 | P23: {=IFERROR(_xlfn.XLOOKUP(1, (Охрана!$A$6:$A$14 = $D23) * 1, _xlfn.XLOOKUP(1, (Охрана!$B$5:$M$5 = P$2) * (Охрана!$B$4:$M$4 = $S$2), Охрана!$B$6:$M$14)), "-")} -> 6910
A24: SHANGHAI | C24: SINOKOR | D24: ВМКТ | E24: {=IFERROR(_xlfn.XLOOKUP(1, (Фрахт!$A$5:$A$80 = $A24)* (Фрахт!$B$5:$B$80 = $C24) * (Фрахт!$C$5:$C$80 =$D24), _xlfn.XLOOKUP(1, (Фрахт!$D$4:$E$4 = E$2) * 1, Фрахт!$D$5:$E$80)) * $S$1, "-")} -> 283500 | F24: {=IFERROR(_xlfn.XLOOKUP(1, (Фрахт!$A$5:$A$80 = $A24)* (Фрахт!$B$5:$B$80 = $C24) * (Фрахт!$C$5:$C$80 =$D24), _xlfn.XLOOKUP(1, (Фрахт!$D$4:$E$4 = F$2) * 1, Фрахт!$D$5:$E$80)) * $S$1, "-")} -> 472500 | G24: {=IFERROR(_xlfn.XLOOKUP(1, ('Drop off'!$A$6:$A$14 = $C24) * 1, _xlfn.XLOOKUP(1, ('Drop off'!$B$5:$I$5 = G$2) * ('Drop off'!$B$4:$I$4 = $S$2), 'Drop off'!$B$6:$I$14)) * $S$1, "-")} -> 56700 | H24: {=IFERROR(_xlfn.XLOOKUP(1, ('Drop off'!$A$6:$A$14 = $C24) * 1, _xlfn.XLOOKUP(1, ('Drop off'!$B$5:$I$5 = H$2) * ('Drop off'!$B$4:$I$4 = $S$2), 'Drop off'!$B$6:$I$14)) * $S$1, "-")} -> 37800 | I24: {=IFERROR(_xlfn.XLOOKUP(1, ('ж.д.'!$A$6:$A$14 = $D24) * 1, _xlfn.XLOOKUP(1, ('ж.д.'!$B$5:$M$5 = I$2) * ('ж.д.'!$B$4:$M$4 = $S$2), 'ж.д.'!$B$6:$M$14)), "-")} -> 125000 | J24: {=IFERROR(_xlfn.XLOOKUP(1, ('ж.д.'!$A$6:$A$14 = $D24) * 1, _xlfn.XLOOKUP(1, ('ж.д.'!$B$5:$M$5 = J$2) * ('ж.д.'!$B$4:$M$4 = $S$2), 'ж.д.'!$B$6:$M$14)), "-")} -> 140000 | K24: {=IFERROR(_xlfn.XLOOKUP(1, ('ж.д.'!$A$6:$A$14 = $D24) * 1, _xlfn.XLOOKUP(1, ('ж.д.'!$B$5:$M$5 = K$2) * ('ж.д.'!$B$4:$M$4 = $S$2), 'ж.д.'!$B$6:$M$14)), "-")} -> 227000 | L24: {=IF(ISNUMBER(SEARCH("Транс",$C24)),_xlfn.XLOOKUP(1,('Фрахт Транс'!$A$5:$A$10=$D24)*1,_xlfn.XLOOKUP(1,('Фрахт Транс'!$B$3:$M$3 = $S$2)*('Фрахт Транс'!$B$4:$M$4=L$2),'Фрахт Транс'!$B$5:$M$10)),SUM($E24, $G24, $I24, $O24))} -> 469300 | M24: {=IF(ISNUMBER(SEARCH("Транс",$C24)),_xlfn.XLOOKUP(1,('Фрахт Транс'!$A$5:$A$10=$D24)*1,_xlfn.XLOOKUP(1,('Фрахт Транс'!$B$3:$M$3=$S$2)*('Фрахт Транс'!$B$4:$M$4=M$2),'Фрахт Транс'!$B$5:$M$10)),SUM($E24, $G24, $J24, $O24))} -> 484300 | N24: {=IF(ISNUMBER(SEARCH("Транс",$C24)),_xlfn.XLOOKUP(1,('Фрахт Транс'!$A$5:$A$10=$D24)*1,_xlfn.XLOOKUP(1,('Фрахт Транс'!$B$3:$M$3=$S$2)*('Фрахт Транс'!$B$4:$M$4=N$2),'Фрахт Транс'!$B$5:$M$10)),SUM($F24, $H24, $K24, $P24))} -> 745500 | O24: {=IFERROR(_xlfn.XLOOKUP(1, (Охрана!$A$6:$A$14 = $D24) * 1, _xlfn.XLOOKUP(1, (Охрана!$B$5:$M$5 = O$2) * (Охрана!$B$4:$M$4 = $S$2), Охрана!$B$6:$M$14)), "-")} -> 4100 | P24: {=IFERROR(_xlfn.XLOOKUP(1, (Охрана!$A$6:$A$14 = $D24) * 1, _xlfn.XLOOKUP(1, (Охрана!$B$5:$M$5 = P$2) * (Охрана!$B$4:$M$4 = $S$2), Охрана!$B$6:$M$14)), "-")} -> 8200
